Workbook

Sheet total rtp
A1: 取几 | B1: 几格 | C1: 原始几率 | D1: 额外倍率几率 | E1: 出现几率 | F1: 重复几格 | G1: 总球数 | H1: 额外倍率 | I1: 原始倍率 | J1: RTP占比 | L1: 总可能 | M1: =COMBIN(G2,5) -> 142506
A2: 9 | B2: 3 | C2: {=INDEX('rtp before multiplier'!H:H,MATCH(1,('rtp before multiplier'!A:A='total rtp'!A2)*('rtp before multiplier'!B:B='total rtp'!B2),0))} -> 0.10742517 | D2: =COMBIN(G2-B2,5-F2)*COMBIN(B2,F2)/$M$1 -> 0.56650246 | E2: =C2*D2 -> 0.060856623 | F2: 0 | G2: 30 | H2: =VLOOKUP(F2,$O$3:$P$8,2,FALSE) -> 1 | I2: 2 | J2: =C2*D2*H2*I2 -> 0.12171325 | K2: =SUM(J2:J35) -> 0.62452039
A3: 9 | B3: 3 | C3: {=INDEX('rtp before multiplier'!H:H,MATCH(1,('rtp before multiplier'!A:A='total rtp'!A3)*('rtp before multiplier'!B:B='total rtp'!B3),0))} -> 0.10742517 | D3: =COMBIN(G3-B3,5-F3)*COMBIN(B3,F3)/$M$1 -> 0.36945813 | E3: =C3*D3 -> 0.039689102 | F3: 1 | G3: 30 | H3: =VLOOKUP(F3,$O$3:$P$8,2,FALSE) -> 2.76 | I3: 2 | J3: =C3*D3*H3*I3 -> 0.21908384 | M3: =SUM(J2:J35) -> 0.62452039 | O3: 0 | P3: =1 -> 1
A4: 9 | B4: 3 | C4: {=INDEX('rtp before multiplier'!H:H,MATCH(1,('rtp before multiplier'!A:A='total rtp'!A4)*('rtp before multiplier'!B:B='total rtp'!B4),0))} -> 0.10742517 | D4: =COMBIN(G4-B4,5-F4)*COMBIN(B4,F4)/$M$1 -> 0.061576355 | E4: =C4*D4 -> 0.0066148503 | F4: 2 | G4: 30 | H4: =VLOOKUP(F4,$O$3:$P$8,2,FALSE) -> 7.6176 | I4: 2 | J4: =C4*D4*H4*I4 -> 0.10077857 | O4: 1 | P4: =multipier!I1 -> 2.76
A5: 9 | B5: 3 | C5: {=INDEX('rtp before multiplier'!H:H,MATCH(1,('rtp before multiplier'!A:A='total rtp'!A5)*('rtp before multiplier'!B:B='total rtp'!B5),0))} -> 0.10742517 | D5: =COMBIN(G5-B5,5-F5)*COMBIN(B5,F5)/$M$1 -> 0.0024630542 | E5: =C5*D5 -> 0.00026459401 | F5: 3 | G5: 30 | H5: =VLOOKUP(F5,$O$3:$P$8,2,FALSE) -> 21.024576 | I5: 2 | J5: =C5*D5*H5*I5 -> 0.011125954 | O5: 2 | P5: =multipier!P1 -> 7.6176
A6: 9 | B6: 5 | C6: {=INDEX('rtp before multiplier'!H:H,MATCH(1,('rtp before multiplier'!A:A='total rtp'!A6)*('rtp before multiplier'!B:B='total rtp'!B6),0))} -> 0.0073756828 | D6: =COMBIN(G6-B6,5-F6)*COMBIN(B6,F6)/$M$1 -> 0.37282641 | E6: =C6*D6 -> 0.0027498493 | F6: 0 | G6: 30 | H6: =VLOOKUP(F6,$O$3:$P$8,2,FALSE) -> 1 | I6: 5 | J6: =C6*D6*H6*I6 -> 0.013749247 | O6: 3 | P6: =multipier!X1 -> 21.024576
A7: 9 | B7: 5 | C7: {=INDEX('rtp before multiplier'!H:H,MATCH(1,('rtp before multiplier'!A:A='total rtp'!A7)*('rtp before multiplier'!B:B='total rtp'!B7),0))} -> 0.0073756828 | D7: =COMBIN(G7-B7,5-F7)*COMBIN(B7,F7)/$M$1 -> 0.44384096 | E7: =C7*D7 -> 0.0032736301 | F7: 1 | G7: 30 | H7: =VLOOKUP(F7,$O$3:$P$8,2,FALSE) -> 2.76 | I7: 5 | J7: =C7*D7*H7*I7 -> 0.045176096 | O7: 4 | P7: =multipier!AG1 -> 58.02783
A8: 9 | B8: 5 | C8: {=INDEX('rtp before multiplier'!H:H,MATCH(1,('rtp before multiplier'!A:A='total rtp'!A8)*('rtp before multiplier'!B:B='total rtp'!B8),0))} -> 0.0073756828 | D8: =COMBIN(G8-B8,5-F8)*COMBIN(B8,F8)/$M$1 -> 0.16139671 | E8: =C8*D8 -> 0.001190411 | F8: 2 | G8: 30 | H8: =VLOOKUP(F8,$O$3:$P$8,2,FALSE) -> 7.6176 | I8: 5 | J8: =C8*D8*H8*I8 -> 0.045340373 | O8: 5 | P8: =multipier!AQ1 -> 160.15681
A9: 9 | B9: 5 | C9: {=INDEX('rtp before multiplier'!H:H,MATCH(1,('rtp before multiplier'!A:A='total rtp'!A9)*('rtp before multiplier'!B:B='total rtp'!B9),0))} -> 0.0073756828 | D9: =COMBIN(G9-B9,5-F9)*COMBIN(B9,F9)/$M$1 -> 0.021051745 | E9: =C9*D9 -> 0.00015527099 | F9: 3 | G9: 30 | H9: =VLOOKUP(F9,$O$3:$P$8,2,FALSE) -> 21.024576 | I9: 5 | J9: =C9*D9*H9*I9 -> 0.016322534
A10: 9 | B10: 5 | C10: {=INDEX('rtp before multiplier'!H:H,MATCH(1,('rtp before multiplier'!A:A='total rtp'!A10)*('rtp before multiplier'!B:B='total rtp'!B10),0))} -> 0.0073756828 | D10: =COMBIN(G10-B10,5-F10)*COMBIN(B10,F10)/$M$1 -> 0.00087715605 | E10: =C10*D10 -> 6.4696248e-06 | F10: 4 | G10: 30 | H10: =VLOOKUP(F10,$O$3:$P$8,2,FALSE) -> 58.02783 | I10: 5 | J10: =C10*D10*H10*I10 -> 0.0018770914 | P10: rtp | Q10: prababilty | R10: hitrate | T10: total rtp | V10: total hitrate
A11: 9 | B11: 5 | C11: {=INDEX('rtp before multiplier'!H:H,MATCH(1,('rtp before multiplier'!A:A='total rtp'!A11)*('rtp before multiplier'!B:B='total rtp'!B11),0))} -> 0.0073756828 | D11: =COMBIN(G11-B11,5-F11)*COMBIN(B11,F11)/$M$1 -> 7.0172484e-06 | E11: =C11*D11 -> 5.1756998e-08 | F11: 5 | G11: 30 | H11: =VLOOKUP(F11,$O$3:$P$8,2,FALSE) -> 160.15681 | I11: 5 | J11: =C11*D11*H11*I11 -> 4.1446179e-05 | O11: 9 | P11: =$K$2 -> 0.62452039 | Q11: =22/31 -> 0.70967742 | R11: =1-'rtp before multiplier'!H2 -> 0.1156361 | T11: =SUMPRODUCT(P11:P15,Q11:Q15) -> 0.96103893 | V11: =SUMPRODUCT(R11:R15,Q11:Q15) -> 0.14630904
A12: 9 | B12: 6 | C12: {=INDEX('rtp before multiplier'!H:H,MATCH(1,('rtp before multiplier'!A:A='total rtp'!A12)*('rtp before multiplier'!B:B='total rtp'!B12),0))} -> 0.00055776308 | D12: =COMBIN(G12-B12,5-F12)*COMBIN(B12,F12)/$M$1 -> 0.29826113 | E12: =C12*D12 -> 0.00016635904 | F12: 0 | G12: 30 | H12: =VLOOKUP(F12,$O$3:$P$8,2,FALSE) -> 1 | I12: 5 | J12: =C12*D12*H12*I12 -> 0.00083179522 | O12: 10 | P12: =$K$36 -> 0.98794165 | Q12: =9/31*0.3 -> 0.087096774 | R12: =1-'rtp before multiplier'!H9 -> 0.16029528
A13: 9 | B13: 6 | C13: {=INDEX('rtp before multiplier'!H:H,MATCH(1,('rtp before multiplier'!A:A='total rtp'!A13)*('rtp before multiplier'!B:B='total rtp'!B13),0))} -> 0.00055776308 | D13: =COMBIN(G13-B13,5-F13)*COMBIN(B13,F13)/$M$1 -> 0.44739169 | E13: =C13*D13 -> 0.00024953856 | F13: 1 | G13: 30 | H13: =VLOOKUP(F13,$O$3:$P$8,2,FALSE) -> 2.76 | I13: 5 | J13: =C13*D13*H13*I13 -> 0.0034436322 | O13: 11 | P13: =$K$70 -> 1.5511061 | Q13: =9/31*0.4 -> 0.11612903 | R13: =1-'rtp before multiplier'!H16 -> 0.21266411
A14: 9 | B14: 6 | C14: {=INDEX('rtp before multiplier'!H:H,MATCH(1,('rtp before multiplier'!A:A='total rtp'!A14)*('rtp before multiplier'!B:B='total rtp'!B14),0))} -> 0.00055776308 | D14: =COMBIN(G14-B14,5-F14)*COMBIN(B14,F14)/$M$1 -> 0.21304366 | E14: =C14*D14 -> 0.00011882789 | F14: 2 | G14: 30 | H14: =VLOOKUP(F14,$O$3:$P$8,2,FALSE) -> 7.6176 | I14: 5 | J14: =C14*D14*H14*I14 -> 0.0045259166 | O14: 12 | P14: =K104 -> 2.4308871 | Q14: =9/31*0.2 -> 0.058064516 | R14: =1-'rtp before multiplier'!H23 -> 0.27202421
A15: 9 | B15: 6 | C15: {=INDEX('rtp before multiplier'!H:H,MATCH(1,('rtp before multiplier'!A:A='total rtp'!A15)*('rtp before multiplier'!B:B='total rtp'!B15),0))} -> 0.00055776308 | D15: =COMBIN(G15-B15,5-F15)*COMBIN(B15,F15)/$M$1 -> 0.038735211 | E15: =C15*D15 -> 2.1605071e-05 | F15: 3 | G15: 30 | H15: =VLOOKUP(F15,$O$3:$P$8,2,FALSE) -> 21.024576 | I15: 5 | J15: =C15*D15*H15*I15 -> 0.0022711872 | O15: 13 | P15: =K138 -> 3.8063745 | Q15: =9/31*0.1 -> 0.029032258 | R15: =1-'rtp before multiplier'!H30 -> 0.33728279
A16: 9 | B16: 6 | C16: {=INDEX('rtp before multiplier'!H:H,MATCH(1,('rtp before multiplier'!A:A='total rtp'!A16)*('rtp before multiplier'!B:B='total rtp'!B16),0))} -> 0.00055776308 | D16: =COMBIN(G16-B16,5-F16)*COMBIN(B16,F16)/$M$1 -> 0.0025262094 | E16: =C16*D16 -> 1.4090263e-06 | F16: 4 | G16: 30 | H16: =VLOOKUP(F16,$O$3:$P$8,2,FALSE) -> 58.02783 | I16: 5 | J16: =C16*D16*H16*I16 -> 0.0004088137
A17: 9 | B17: 6 | C17: {=INDEX('rtp before multiplier'!H:H,MATCH(1,('rtp before multiplier'!A:A='total rtp'!A17)*('rtp before multiplier'!B:B='total rtp'!B17),0))} -> 0.00055776308 | D17: =COMBIN(G17-B17,5-F17)*COMBIN(B17,F17)/$M$1 -> 4.210349e-05 | E17: =C17*D17 -> 2.3483772e-08 | F17: 5 | G17: 30 | H17: =VLOOKUP(F17,$O$3:$P$8,2,FALSE) -> 160.15681 | I17: 5 | J17: =C17*D17*H17*I17 -> 1.880543e-05
A18: 9 | B18: 7 | C18: {=INDEX('rtp before multiplier'!H:H,MATCH(1,('rtp before multiplier'!A:A='total rtp'!A18)*('rtp before multiplier'!B:B='total rtp'!B18),0))} -> 0.00026420356 | D18: =COMBIN(G18-B18,5-F18)*COMBIN(B18,F18)/$M$1 -> 0.23612339 | E18: =C18*D18 -> 6.2384641e-05 | F18: 0 | G18: 30 | H18: =VLOOKUP(F18,$O$3:$P$8,2,FALSE) -> 1 | I18: 25 | J18: =C18*D18*H18*I18 -> 0.001559616
A19: 9 | B19: 7 | C19: {=INDEX('rtp before multiplier'!H:H,MATCH(1,('rtp before multiplier'!A:A='total rtp'!A19)*('rtp before multiplier'!B:B='total rtp'!B19),0))} -> 0.00026420356 | D19: =COMBIN(G19-B19,5-F19)*COMBIN(B19,F19)/$M$1 -> 0.43496414 | E19: =C19*D19 -> 0.00011491908 | F19: 1 | G19: 30 | H19: =VLOOKUP(F19,$O$3:$P$8,2,FALSE) -> 2.76 | I19: 25 | J19: =C19*D19*H19*I19 -> 0.0079294162
A20: 9 | B20: 7 | C20: {=INDEX('rtp before multiplier'!H:H,MATCH(1,('rtp before multiplier'!A:A='total rtp'!A20)*('rtp before multiplier'!B:B='total rtp'!B20),0))} -> 0.00026420356 | D20: =COMBIN(G20-B20,5-F20)*COMBIN(B20,F20)/$M$1 -> 0.26097849 | E20: =C20*D20 -> 6.8951446e-05 | F20: 2 | G20: 30 | H20: =VLOOKUP(F20,$O$3:$P$8,2,FALSE) -> 7.6176 | I20: 25 | J20: =C20*D20*H20*I20 -> 0.013131113
A21: 9 | B21: 7 | C21: {=INDEX('rtp before multiplier'!H:H,MATCH(1,('rtp before multiplier'!A:A='total rtp'!A21)*('rtp before multiplier'!B:B='total rtp'!B21),0))} -> 0.00026420356 | D21: =COMBIN(G21-B21,5-F21)*COMBIN(B21,F21)/$M$1 -> 0.062137735 | E21: =C21*D21 -> 1.6417011e-05 | F21: 3 | G21: 30 | H21: =VLOOKUP(F21,$O$3:$P$8,2,FALSE) -> 21.024576 | I21: 25 | J21: =C21*D21*H21*I21 -> 0.0086290173
A22: 9 | B22: 7 | C22: {=INDEX('rtp before multiplier'!H:H,MATCH(1,('rtp before multiplier'!A:A='total rtp'!A22)*('rtp before multiplier'!B:B='total rtp'!B22),0))} -> 0.00026420356 | D22: =COMBIN(G22-B22,5-F22)*COMBIN(B22,F22)/$M$1 -> 0.005648885 | E22: =C22*D22 -> 1.4924555e-06 | F22: 4 | G22: 30 | H22: =VLOOKUP(F22,$O$3:$P$8,2,FALSE) -> 58.02783 | I22: 25 | J22: =C22*D22*H22*I22 -> 0.0021650989
A23: 9 | B23: 7 | C23: {=INDEX('rtp before multiplier'!H:H,MATCH(1,('rtp before multiplier'!A:A='total rtp'!A23)*('rtp before multiplier'!B:B='total rtp'!B23),0))} -> 0.00026420356 | D23: =COMBIN(G23-B23,5-F23)*COMBIN(B23,F23)/$M$1 -> 0.00014736222 | E23: =C23*D23 -> 3.8933623e-08 | F23: 5 | G23: 30 | H23: =VLOOKUP(F23,$O$3:$P$8,2,FALSE) -> 160.15681 | I23: 25 | J23: =C23*D23*H23*I23 -> 0.00015588712
A24: 9 | B24: 8 | C24: {=INDEX('rtp before multiplier'!H:H,MATCH(1,('rtp before multiplier'!A:A='total rtp'!A24)*('rtp before multiplier'!B:B='total rtp'!B24),0))} -> 1.3210178e-05 | D24: =COMBIN(G24-B24,5-F24)*COMBIN(B24,F24)/$M$1 -> 0.18479222 | E24: =C24*D24 -> 2.4411381e-06 | F24: 0 | G24: 30 | H24: =VLOOKUP(F24,$O$3:$P$8,2,FALSE) -> 1 | I24: 50 | J24: =C24*D24*H24*I24 -> 0.00012205691
A25: 9 | B25: 8 | C25: {=INDEX('rtp before multiplier'!H:H,MATCH(1,('rtp before multiplier'!A:A='total rtp'!A25)*('rtp before multiplier'!B:B='total rtp'!B25),0))} -> 1.3210178e-05 | D25: =COMBIN(G25-B25,5-F25)*COMBIN(B25,F25)/$M$1 -> 0.41064938 | E25: =C25*D25 -> 5.4247514e-06 | F25: 1 | G25: 30 | H25: =VLOOKUP(F25,$O$3:$P$8,2,FALSE) -> 2.76 | I25: 50 | J25: =C25*D25*H25*I25 -> 0.00074861569
A26: 9 | B26: 8 | C26: {=INDEX('rtp before multiplier'!H:H,MATCH(1,('rtp before multiplier'!A:A='total rtp'!A26)*('rtp before multiplier'!B:B='total rtp'!B26),0))} -> 1.3210178e-05 | D26: =COMBIN(G26-B26,5-F26)*COMBIN(B26,F26)/$M$1 -> 0.30258375 | E26: =C26*D26 -> 3.9971852e-06 | F26: 2 | G26: 30 | H26: =VLOOKUP(F26,$O$3:$P$8,2,FALSE) -> 7.6176 | I26: 50 | J26: =C26*D26*H26*I26 -> 0.0015224479
A27: 9 | B27: 8 | C27: {=INDEX('rtp before multiplier'!H:H,MATCH(1,('rtp before multiplier'!A:A='total rtp'!A27)*('rtp before multiplier'!B:B='total rtp'!B27),0))} -> 1.3210178e-05 | D27: =COMBIN(G27-B27,5-F27)*COMBIN(B27,F27)/$M$1 -> 0.090775125 | E27: =C27*D27 -> 1.1991556e-06 | F27: 3 | G27: 30 | H27: =VLOOKUP(F27,$O$3:$P$8,2,FALSE) -> 21.024576 | I27: 50 | J27: =C27*D27*H27*I27 -> 0.0012605869
... A34: 9 | B34: 9 | C34: {=INDEX('rtp before multiplier'!H:H,MATCH(1,('rtp before multiplier'!A:A='total rtp'!A34)*('rtp before multiplier'!B:B='total rtp'!B34),0))} -> 6.9895122e-08 | D34: =COMBIN(G34-B34,5-F34)*COMBIN(B34,F34)/$M$1 -> 0.018567639 | E34: =C34*D34 -> 1.2977874e-09 | F34: 4 | G34: 30 | H34: =VLOOKUP(F34,$O$3:$P$8,2,FALSE) -> 58.02783 | I34: 250 | J34: =C34*D34*H34*I34 -> 1.8826947e-05
A35: 9 | B35: 9 | C35: {=INDEX('rtp before multiplier'!H:H,MATCH(1,('rtp before multiplier'!A:A='total rtp'!A35)*('rtp before multiplier'!B:B='total rtp'!B35),0))} -> 6.9895122e-08 | D35: =COMBIN(G35-B35,5-F35)*COMBIN(B35,F35)/$M$1 -> 0.0008841733 | E35: =C35*D35 -> 6.1799401e-11 | F35: 5 | G35: 30 | H35: =VLOOKUP(F35,$O$3:$P$8,2,FALSE) -> 160.15681 | I35: 250 | J35: =C35*D35*H35*I35 -> 2.4743987e-06 | L35: =D35*C35 -> 6.1799401e-11 | M35: =1/L35 -> 1.6181387e+10
A36: 10 | B36: 3 | C36: {=INDEX('rtp before multiplier'!H:H,MATCH(1,('rtp before multiplier'!A:A='total rtp'!A36)*('rtp before multiplier'!B:B='total rtp'!B36),0))} -> 0.14417606 | D36: =COMBIN(G36-B36,5-F36)*COMBIN(B36,F36)/$M$1 -> 0.56650246 | E36: =C36*D36 -> 0.081676095 | F36: 0 | G36: 30 | H36: =VLOOKUP(F36,$O$3:$P$8,2,FALSE) -> 1 | I36: 2 | J36: =C36*D36*H36*I36 -> 0.16335219 | K36: =SUM(J36:J69) -> 0.98794165
A37: 10 | B37: 3 | C37: {=INDEX('rtp before multiplier'!H:H,MATCH(1,('rtp before multiplier'!A:A='total rtp'!A37)*('rtp before multiplier'!B:B='total rtp'!B37),0))} -> 0.14417606 | D37: =COMBIN(G37-B37,5-F37)*COMBIN(B37,F37)/$M$1 -> 0.36945813 | E37: =C37*D37 -> 0.053267019 | F37: 1 | G37: 30 | H37: =VLOOKUP(F37,$O$3:$P$8,2,FALSE) -> 2.76 | I37: 2 | J37: =C37*D37*H37*I37 -> 0.29403394
A38: 10 | B38: 3 | C38: {=INDEX('rtp before multiplier'!H:H,MATCH(1,('rtp before multiplier'!A:A='total rtp'!A38)*('rtp before multiplier'!B:B='total rtp'!B38),0))} -> 0.14417606 | D38: =COMBIN(G38-B38,5-F38)*COMBIN(B38,F38)/$M$1 -> 0.061576355 | E38: =C38*D38 -> 0.0088778364 | F38: 2 | G38: 30 | H38: =VLOOKUP(F38,$O$3:$P$8,2,FALSE) -> 7.6176 | I38: 2 | J38: =C38*D38*H38*I38 -> 0.13525561
A39: 10 | B39: 3 | C39: {=INDEX('rtp before multiplier'!H:H,MATCH(1,('rtp before multiplier'!A:A='total rtp'!A39)*('rtp before multiplier'!B:B='total rtp'!B39),0))} -> 0.14417606 | D39: =COMBIN(G39-B39,5-F39)*COMBIN(B39,F39)/$M$1 -> 0.0024630542 | E39: =C39*D39 -> 0.00035511346 | F39: 3 | G39: 30 | H39: =VLOOKUP(F39,$O$3:$P$8,2,FALSE) -> 21.024576 | I39: 2 | J39: =C39*D39*H39*I39 -> 0.01493222
A40: 10 | B40: 5 | C40: {=INDEX('rtp before multiplier'!H:H,MATCH(1,('rtp before multiplier'!A:A='total rtp'!A40)*('rtp before multiplier'!B:B='total rtp'!B40),0))} -> 0.014063598 | D40: =COMBIN(G40-B40,5-F40)*COMBIN(B40,F40)/$M$1 -> 0.37282641 | E40: =C40*D40 -> 0.0052432806 | F40: 0 | G40: 30 | H40: =VLOOKUP(F40,$O$3:$P$8,2,FALSE) -> 1 | I40: 5 | J40: =C40*D40*H40*I40 -> 0.026216403
A41: 10 | B41: 5 | C41: {=INDEX('rtp before multiplier'!H:H,MATCH(1,('rtp before multiplier'!A:A='total rtp'!A41)*('rtp before multiplier'!B:B='total rtp'!B41),0))} -> 0.014063598 | D41: =COMBIN(G41-B41,5-F41)*COMBIN(B41,F41)/$M$1 -> 0.44384096 | E41: =C41*D41 -> 0.0062420007 | F41: 1 | G41: 30 | H41: =VLOOKUP(F41,$O$3:$P$8,2,FALSE) -> 2.76 | I41: 5 | J41: =C41*D41*H41*I41 -> 0.086139609
A42: 10 | B42: 5 | C42: {=INDEX('rtp before multiplier'!H:H,MATCH(1,('rtp before multiplier'!A:A='total rtp'!A42)*('rtp before multiplier'!B:B='total rtp'!B42),0))} -> 0.014063598 | D42: =COMBIN(G42-B42,5-F42)*COMBIN(B42,F42)/$M$1 -> 0.16139671 | E42: =C42*D42 -> 0.0022698184 | F42: 2 | G42: 30 | H42: =VLOOKUP(F42,$O$3:$P$8,2,FALSE) -> 7.6176 | I42: 5 | J42: =C42*D42*H42*I42 -> 0.086452844
A43: 10 | B43: 5 | C43: {=INDEX('rtp before multiplier'!H:H,MATCH(1,('rtp before multiplier'!A:A='total rtp'!A43)*('rtp before multiplier'!B:B='total rtp'!B43),0))} -> 0.014063598 | D43: =COMBIN(G43-B43,5-F43)*COMBIN(B43,F43)/$M$1 -> 0.021051745 | E43: =C43*D43 -> 0.00029606327 | F43: 3 | G43: 30 | H43: =VLOOKUP(F43,$O$3:$P$8,2,FALSE) -> 21.024576 | I43: 5 | J43: =C43*D43*H43*I43 -> 0.031123024
A44: 10 | B44: 5 | C44: {=INDEX('rtp before multiplier'!H:H,MATCH(1,('rtp before multiplier'!A:A='total rtp'!A44)*('rtp before multiplier'!B:B='total rtp'!B44),0))} -> 0.014063598 | D44: =COMBIN(G44-B44,5-F44)*COMBIN(B44,F44)/$M$1 -> 0.00087715605 | E44: =C44*D44 -> 1.233597e-05 | F44: 4 | G44: 30 | H44: =VLOOKUP(F44,$O$3:$P$8,2,FALSE) -> 58.02783 | I44: 5 | J44: =C44*D44*H44*I44 -> 0.0035791477
A45: 10 | B45: 5 | C45: {=INDEX('rtp before multiplier'!H:H,MATCH(1,('rtp before multiplier'!A:A='total rtp'!A45)*('rtp before multiplier'!B:B='total rtp'!B45),0))} -> 0.014063598 | D45: =COMBIN(G45-B45,5-F45)*COMBIN(B45,F45)/$M$1 -> 7.0172484e-06 | E45: =C45*D45 -> 9.8687758e-08 | F45: 5 | G45: 30 | H45: =VLOOKUP(F45,$O$3:$P$8,2,FALSE) -> 160.15681 | I45: 5 | J45: =C45*D45*H45*I45 -> 7.9027582e-05
A46: 10 | B46: 6 | C46: {=INDEX('rtp before multiplier'!H:H,MATCH(1,('rtp before multiplier'!A:A='total rtp'!A46)*('rtp before multiplier'!B:B='total rtp'!B46),0))} -> 0.0011952066 | D46: =COMBIN(G46-B46,5-F46)*COMBIN(B46,F46)/$M$1 -> 0.29826113 | E46: =C46*D46 -> 0.00035648366 | F46: 0 | G46: 30 | H46: =VLOOKUP(F46,$O$3:$P$8,2,FALSE) -> 1 | I46: 5 | J46: =C46*D46*H46*I46 -> 0.0017824183
...

Sheet line prabability check
B1: A1 | C1: A2 | D1: A3 | E1: B1 | F1: B2 | G1: B3 | H1: C1 | I1: C2 | J1: C3 | L1: LC | M1: MC | N1: RC | O1: UR | P1: MR | Q1: DR | V1: A1 | W1: A2 | X1: A3 | Y1: B1 | Z1: B2 | AA1: B3 | AB1: C1 | AC1: C2 | AD1: C3
B2: 1 | C2: 1 | D2: 1 | E2: 1 | F2: 1 | G2: 1 | H2: 1 | I2: 1 | J2: 1 | L2: =AND($B2>=$V$2,$C2>=$W$2,$D2>=$X$2,$E2>=$Y$2,$F2>=$Z$2,$G2>=$AA$2,$H2>=$AB$2,$I2>=$AC$2,$J2>=$AD$2) -> TRUE | M2: =AND($B2>=$V$3,$C2>=$W$3,$D2>=$X$3,$E2>=$Y$3,$F2>=$Z$3,$G2>=$AA$3,$H2>=$AB$3,$I2>=$AC$3,$J2>=$AD$3) -> TRUE | N2: =AND($B2>=$V$4,$C2>=$W$4,$D2>=$X$4,$E2>=$Y$4,$F2>=$Z$4,$G2>=$AA$4,$H2>=$AB$4,$I2>=$AC$4,$J2>=$AD$4) -> TRUE | O2: =AND($B2>=$V$5,$C2>=$W$5,$D2>=$X$5,$E2>=$Y$5,$F2>=$Z$5,$G2>=$AA$5,$H2>=$AB$5,$I2>=$AC$5,$J2>=$AD$5) -> TRUE | P2: =AND($B2>=$V$6,$C2>=$W$6,$D2>=$X$6,$E2>=$Y$6,$F2>=$Z$6,$G2>=$AA$6,$H2>=$AB$6,$I2>=$AC$6,$J2>=$AD$6) -> TRUE | Q2: =AND($B2>=$V$7,$C2>=$W$7,$D2>=$X$7,$E2>=$Y$7,$F2>=$Z$7,$G2>=$AA$7,$H2>=$AB$7,$I2>=$AC$7,$J2>=$AD$7) -> TRUE | U2: LC | V2: 1 | W2: 1 | X2: 1
B3: 1 | C3: 1 | D3: 1 | E3: 1 | F3: 1 | G3: 1 | H3: 1 | I3: 1 | J3: 0 | L3: =AND($B3>=$V$2,$C3>=$W$2,$D3>=$X$2,$E3>=$Y$2,$F3>=$Z$2,$G3>=$AA$2,$H3>=$AB$2,$I3>=$AC$2,$J3>=$AD$2) -> TRUE | M3: =AND($B3>=$V$3,$C3>=$W$3,$D3>=$X$3,$E3>=$Y$3,$F3>=$Z$3,$G3>=$AA$3,$H3>=$AB$3,$I3>=$AC$3,$J3>=$AD$3) -> TRUE | N3: =AND($B3>=$V$4,$C3>=$W$4,$D3>=$X$4,$E3>=$Y$4,$F3>=$Z$4,$G3>=$AA$4,$H3>=$AB$4,$I3>=$AC$4,$J3>=$AD$4) -> FALSE | O3: =AND($B3>=$V$5,$C3>=$W$5,$D3>=$X$5,$E3>=$Y$5,$F3>=$Z$5,$G3>=$AA$5,$H3>=$AB$5,$I3>=$AC$5,$J3>=$AD$5) -> TRUE | P3: =AND($B3>=$V$6,$C3>=$W$6,$D3>=$X$6,$E3>=$Y$6,$F3>=$Z$6,$G3>=$AA$6,$H3>=$AB$6,$I3>=$AC$6,$J3>=$AD$6) -> TRUE | Q3: =AND($B3>=$V$7,$C3>=$W$7,$D3>=$X$7,$E3>=$Y$7,$F3>=$Z$7,$G3>=$AA$7,$H3>=$AB$7,$I3>=$AC$7,$J3>=$AD$7) -> FALSE | U3: MC | Y3: 1 | Z3: 1 | AA3: 1
B4: 1 | C4: 1 | D4: 1 | E4: 1 | F4: 1 | G4: 1 | H4: 1 | I4: 0 | J4: 1 | L4: =AND($B4>=$V$2,$C4>=$W$2,$D4>=$X$2,$E4>=$Y$2,$F4>=$Z$2,$G4>=$AA$2,$H4>=$AB$2,$I4>=$AC$2,$J4>=$AD$2) -> TRUE | M4: =AND($B4>=$V$3,$C4>=$W$3,$D4>=$X$3,$E4>=$Y$3,$F4>=$Z$3,$G4>=$AA$3,$H4>=$AB$3,$I4>=$AC$3,$J4>=$AD$3) -> TRUE | N4: =AND($B4>=$V$4,$C4>=$W$4,$D4>=$X$4,$E4>=$Y$4,$F4>=$Z$4,$G4>=$AA$4,$H4>=$AB$4,$I4>=$AC$4,$J4>=$AD$4) -> FALSE | O4: =AND($B4>=$V$5,$C4>=$W$5,$D4>=$X$5,$E4>=$Y$5,$F4>=$Z$5,$G4>=$AA$5,$H4>=$AB$5,$I4>=$AC$5,$J4>=$AD$5) -> TRUE | P4: =AND($B4>=$V$6,$C4>=$W$6,$D4>=$X$6,$E4>=$Y$6,$F4>=$Z$6,$G4>=$AA$6,$H4>=$AB$6,$I4>=$AC$6,$J4>=$AD$6) -> FALSE | Q4: =AND($B4>=$V$7,$C4>=$W$7,$D4>=$X$7,$E4>=$Y$7,$F4>=$Z$7,$G4>=$AA$7,$H4>=$AB$7,$I4>=$AC$7,$J4>=$AD$7) -> TRUE | U4: RC | AB4: 1 | AC4: 1 | AD4: 1
B5: 1 | C5: 1 | D5: 1 | E5: 1 | F5: 1 | G5: 1 | H5: 1 | I5: 0 | J5: 0 | L5: =AND($B5>=$V$2,$C5>=$W$2,$D5>=$X$2,$E5>=$Y$2,$F5>=$Z$2,$G5>=$AA$2,$H5>=$AB$2,$I5>=$AC$2,$J5>=$AD$2) -> TRUE | M5: =AND($B5>=$V$3,$C5>=$W$3,$D5>=$X$3,$E5>=$Y$3,$F5>=$Z$3,$G5>=$AA$3,$H5>=$AB$3,$I5>=$AC$3,$J5>=$AD$3) -> TRUE | N5: =AND($B5>=$V$4,$C5>=$W$4,$D5>=$X$4,$E5>=$Y$4,$F5>=$Z$4,$G5>=$AA$4,$H5>=$AB$4,$I5>=$AC$4,$J5>=$AD$4) -> FALSE | O5: =AND($B5>=$V$5,$C5>=$W$5,$D5>=$X$5,$E5>=$Y$5,$F5>=$Z$5,$G5>=$AA$5,$H5>=$AB$5,$I5>=$AC$5,$J5>=$AD$5) -> TRUE | P5: =AND($B5>=$V$6,$C5>=$W$6,$D5>=$X$6,$E5>=$Y$6,$F5>=$Z$6,$G5>=$AA$6,$H5>=$AB$6,$I5>=$AC$6,$J5>=$AD$6) -> FALSE | Q5: =AND($B5>=$V$7,$C5>=$W$7,$D5>=$X$7,$E5>=$Y$7,$F5>=$Z$7,$G5>=$AA$7,$H5>=$AB$7,$I5>=$AC$7,$J5>=$AD$7) -> FALSE | U5: UR | V5: 1 | Y5: 1 | AB5: 1
B6: 1 | C6: 1 | D6: 1 | E6: 1 | F6: 1 | G6: 1 | H6: 0 | I6: 1 | J6: 1 | L6: =AND($B6>=$V$2,$C6>=$W$2,$D6>=$X$2,$E6>=$Y$2,$F6>=$Z$2,$G6>=$AA$2,$H6>=$AB$2,$I6>=$AC$2,$J6>=$AD$2) -> TRUE | M6: =AND($B6>=$V$3,$C6>=$W$3,$D6>=$X$3,$E6>=$Y$3,$F6>=$Z$3,$G6>=$AA$3,$H6>=$AB$3,$I6>=$AC$3,$J6>=$AD$3) -> TRUE | N6: =AND($B6>=$V$4,$C6>=$W$4,$D6>=$X$4,$E6>=$Y$4,$F6>=$Z$4,$G6>=$AA$4,$H6>=$AB$4,$I6>=$AC$4,$J6>=$AD$4) -> FALSE | O6: =AND($B6>=$V$5,$C6>=$W$5,$D6>=$X$5,$E6>=$Y$5,$F6>=$Z$5,$G6>=$AA$5,$H6>=$AB$5,$I6>=$AC$5,$J6>=$AD$5) -> FALSE | P6: =AND($B6>=$V$6,$C6>=$W$6,$D6>=$X$6,$E6>=$Y$6,$F6>=$Z$6,$G6>=$AA$6,$H6>=$AB$6,$I6>=$AC$6,$J6>=$AD$6) -> TRUE | Q6: =AND($B6>=$V$7,$C6>=$W$7,$D6>=$X$7,$E6>=$Y$7,$F6>=$Z$7,$G6>=$AA$7,$H6>=$AB$7,$I6>=$AC$7,$J6>=$AD$7) -> TRUE | U6: MR | W6: 1 | Z6: 1 | AC6: 1
B7: 1 | C7: 1 | D7: 1 | E7: 1 | F7: 1 | G7: 1 | H7: 0 | I7: 1 | J7: 0 | L7: =AND($B7>=$V$2,$C7>=$W$2,$D7>=$X$2,$E7>=$Y$2,$F7>=$Z$2,$G7>=$AA$2,$H7>=$AB$2,$I7>=$AC$2,$J7>=$AD$2) -> TRUE | M7: =AND($B7>=$V$3,$C7>=$W$3,$D7>=$X$3,$E7>=$Y$3,$F7>=$Z$3,$G7>=$AA$3,$H7>=$AB$3,$I7>=$AC$3,$J7>=$AD$3) -> TRUE | N7: =AND($B7>=$V$4,$C7>=$W$4,$D7>=$X$4,$E7>=$Y$4,$F7>=$Z$4,$G7>=$AA$4,$H7>=$AB$4,$I7>=$AC$4,$J7>=$AD$4) -> FALSE | O7: =AND($B7>=$V$5,$C7>=$W$5,$D7>=$X$5,$E7>=$Y$5,$F7>=$Z$5,$G7>=$AA$5,$H7>=$AB$5,$I7>=$AC$5,$J7>=$AD$5) -> FALSE | P7: =AND($B7>=$V$6,$C7>=$W$6,$D7>=$X$6,$E7>=$Y$6,$F7>=$Z$6,$G7>=$AA$6,$H7>=$AB$6,$I7>=$AC$6,$J7>=$AD$6) -> TRUE | Q7: =AND($B7>=$V$7,$C7>=$W$7,$D7>=$X$7,$E7>=$Y$7,$F7>=$Z$7,$G7>=$AA$7,$H7>=$AB$7,$I7>=$AC$7,$J7>=$AD$7) -> FALSE | U7: DR | X7: 1 | AA7: 1 | AD7: 1
B8: 1 | C8: 1 | D8: 1 | E8: 1 | F8: 1 | G8: 1 | H8: 0 | I8: 0 | J8: 1 | L8: =AND($B8>=$V$2,$C8>=$W$2,$D8>=$X$2,$E8>=$Y$2,$F8>=$Z$2,$G8>=$AA$2,$H8>=$AB$2,$I8>=$AC$2,$J8>=$AD$2) -> TRUE | M8: =AND($B8>=$V$3,$C8>=$W$3,$D8>=$X$3,$E8>=$Y$3,$F8>=$Z$3,$G8>=$AA$3,$H8>=$AB$3,$I8>=$AC$3,$J8>=$AD$3) -> TRUE | N8: =AND($B8>=$V$4,$C8>=$W$4,$D8>=$X$4,$E8>=$Y$4,$F8>=$Z$4,$G8>=$AA$4,$H8>=$AB$4,$I8>=$AC$4,$J8>=$AD$4) -> FALSE | O8: =AND($B8>=$V$5,$C8>=$W$5,$D8>=$X$5,$E8>=$Y$5,$F8>=$Z$5,$G8>=$AA$5,$H8>=$AB$5,$I8>=$AC$5,$J8>=$AD$5) -> FALSE | P8: =AND($B8>=$V$6,$C8>=$W$6,$D8>=$X$6,$E8>=$Y$6,$F8>=$Z$6,$G8>=$AA$6,$H8>=$AB$6,$I8>=$AC$6,$J8>=$AD$6) -> FALSE | Q8: =AND($B8>=$V$7,$C8>=$W$7,$D8>=$X$7,$E8>=$Y$7,$F8>=$Z$7,$G8>=$AA$7,$H8>=$AB$7,$I8>=$AC$7,$J8>=$AD$7) -> TRUE
B9: 1 | C9: 1 | D9: 1 | E9: 1 | F9: 1 | G9: 1 | H9: 0 | I9: 0 | J9: 0 | L9: =AND($B9>=$V$2,$C9>=$W$2,$D9>=$X$2,$E9>=$Y$2,$F9>=$Z$2,$G9>=$AA$2,$H9>=$AB$2,$I9>=$AC$2,$J9>=$AD$2) -> TRUE | M9: =AND($B9>=$V$3,$C9>=$W$3,$D9>=$X$3,$E9>=$Y$3,$F9>=$Z$3,$G9>=$AA$3,$H9>=$AB$3,$I9>=$AC$3,$J9>=$AD$3) -> TRUE | N9: =AND($B9>=$V$4,$C9>=$W$4,$D9>=$X$4,$E9>=$Y$4,$F9>=$Z$4,$G9>=$AA$4,$H9>=$AB$4,$I9>=$AC$4,$J9>=$AD$4) -> FALSE | O9: =AND($B9>=$V$5,$C9>=$W$5,$D9>=$X$5,$E9>=$Y$5,$F9>=$Z$5,$G9>=$AA$5,$H9>=$AB$5,$I9>=$AC$5,$J9>=$AD$5) -> FALSE | P9: =AND($B9>=$V$6,$C9>=$W$6,$D9>=$X$6,$E9>=$Y$6,$F9>=$Z$6,$G9>=$AA$6,$H9>=$AB$6,$I9>=$AC$6,$J9>=$AD$6) -> FALSE | Q9: =AND($B9>=$V$7,$C9>=$W$7,$D9>=$X$7,$E9>=$Y$7,$F9>=$Z$7,$G9>=$AA$7,$H9>=$AB$7,$I9>=$AC$7,$J9>=$AD$7) -> FALSE
B10: 1 | C10: 1 | D10: 1 | E10: 1 | F10: 1 | G10: 0 | H10: 1 | I10: 1 | J10: 1 | L10: =AND($B10>=$V$2,$C10>=$W$2,$D10>=$X$2,$E10>=$Y$2,$F10>=$Z$2,$G10>=$AA$2,$H10>=$AB$2,$I10>=$AC$2,$J10>=$AD$2) -> TRUE | M10: =AND($B10>=$V$3,$C10>=$W$3,$D10>=$X$3,$E10>=$Y$3,$F10>=$Z$3,$G10>=$AA$3,$H10>=$AB$3,$I10>=$AC$3,$J10>=$AD$3) -> FALSE | N10: =AND($B10>=$V$4,$C10>=$W$4,$D10>=$X$4,$E10>=$Y$4,$F10>=$Z$4,$G10>=$AA$4,$H10>=$AB$4,$I10>=$AC$4,$J10>=$AD$4) -> TRUE | O10: =AND($B10>=$V$5,$C10>=$W$5,$D10>=$X$5,$E10>=$Y$5,$F10>=$Z$5,$G10>=$AA$5,$H10>=$AB$5,$I10>=$AC$5,$J10>=$AD$5) -> TRUE | P10: =AND($B10>=$V$6,$C10>=$W$6,$D10>=$X$6,$E10>=$Y$6,$F10>=$Z$6,$G10>=$AA$6,$H10>=$AB$6,$I10>=$AC$6,$J10>=$AD$6) -> TRUE | Q10: =AND($B10>=$V$7,$C10>=$W$7,$D10>=$X$7,$E10>=$Y$7,$F10>=$Z$7,$G10>=$AA$7,$H10>=$AB$7,$I10>=$AC$7,$J10>=$AD$7) -> FALSE
B11: 1 | C11: 1 | D11: 1 | E11: 1 | F11: 1 | G11: 0 | H11: 1 | I11: 1 | J11: 0 | L11: =AND($B11>=$V$2,$C11>=$W$2,$D11>=$X$2,$E11>=$Y$2,$F11>=$Z$2,$G11>=$AA$2,$H11>=$AB$2,$I11>=$AC$2,$J11>=$AD$2) -> TRUE | M11: =AND($B11>=$V$3,$C11>=$W$3,$D11>=$X$3,$E11>=$Y$3,$F11>=$Z$3,$G11>=$AA$3,$H11>=$AB$3,$I11>=$AC$3,$J11>=$AD$3) -> FALSE | N11: =AND($B11>=$V$4,$C11>=$W$4,$D11>=$X$4,$E11>=$Y$4,$F11>=$Z$4,$G11>=$AA$4,$H11>=$AB$4,$I11>=$AC$4,$J11>=$AD$4) -> FALSE | O11: =AND($B11>=$V$5,$C11>=$W$5,$D11>=$X$5,$E11>=$Y$5,$F11>=$Z$5,$G11>=$AA$5,$H11>=$AB$5,$I11>=$AC$5,$J11>=$AD$5) -> TRUE | P11: =AND($B11>=$V$6,$C11>=$W$6,$D11>=$X$6,$E11>=$Y$6,$F11>=$Z$6,$G11>=$AA$6,$H11>=$AB$6,$I11>=$AC$6,$J11>=$AD$6) -> TRUE | Q11: =AND($B11>=$V$7,$C11>=$W$7,$D11>=$X$7,$E11>=$Y$7,$F11>=$Z$7,$G11>=$AA$7,$H11>=$AB$7,$I11>=$AC$7,$J11>=$AD$7) -> FALSE
B12: 1 | C12: 1 | D12: 1 | E12: 1 | F12: 1 | G12: 0 | H12: 1 | I12: 0 | J12: 1 | L12: =AND($B12>=$V$2,$C12>=$W$2,$D12>=$X$2,$E12>=$Y$2,$F12>=$Z$2,$G12>=$AA$2,$H12>=$AB$2,$I12>=$AC$2,$J12>=$AD$2) -> TRUE | M12: =AND($B12>=$V$3,$C12>=$W$3,$D12>=$X$3,$E12>=$Y$3,$F12>=$Z$3,$G12>=$AA$3,$H12>=$AB$3,$I12>=$AC$3,$J12>=$AD$3) -> FALSE | N12: =AND($B12>=$V$4,$C12>=$W$4,$D12>=$X$4,$E12>=$Y$4,$F12>=$Z$4,$G12>=$AA$4,$H12>=$AB$4,$I12>=$AC$4,$J12>=$AD$4) -> FALSE | O12: =AND($B12>=$V$5,$C12>=$W$5,$D12>=$X$5,$E12>=$Y$5,$F12>=$Z$5,$G12>=$AA$5,$H12>=$AB$5,$I12>=$AC$5,$J12>=$AD$5) -> TRUE | P12: =AND($B12>=$V$6,$C12>=$W$6,$D12>=$X$6,$E12>=$Y$6,$F12>=$Z$6,$G12>=$AA$6,$H12>=$AB$6,$I12>=$AC$6,$J12>=$AD$6) -> FALSE | Q12: =AND($B12>=$V$7,$C12>=$W$7,$D12>=$X$7,$E12>=$Y$7,$F12>=$Z$7,$G12>=$AA$7,$H12>=$AB$7,$I12>=$AC$7,$J12>=$AD$7) -> FALSE
B13: 1 | C13: 1 | D13: 1 | E13: 1 | F13: 1 | G13: 0 | H13: 1 | I13: 0 | J13: 0 | L13: =AND($B13>=$V$2,$C13>=$W$2,$D13>=$X$2,$E13>=$Y$2,$F13>=$Z$2,$G13>=$AA$2,$H13>=$AB$2,$I13>=$AC$2,$J13>=$AD$2) -> TRUE | M13: =AND($B13>=$V$3,$C13>=$W$3,$D13>=$X$3,$E13>=$Y$3,$F13>=$Z$3,$G13>=$AA$3,$H13>=$AB$3,$I13>=$AC$3,$J13>=$AD$3) -> FALSE | N13: =AND($B13>=$V$4,$C13>=$W$4,$D13>=$X$4,$E13>=$Y$4,$F13>=$Z$4,$G13>=$AA$4,$H13>=$AB$4,$I13>=$AC$4,$J13>=$AD$4) -> FALSE | O13: =AND($B13>=$V$5,$C13>=$W$5,$D13>=$X$5,$E13>=$Y$5,$F13>=$Z$5,$G13>=$AA$5,$H13>=$AB$5,$I13>=$AC$5,$J13>=$AD$5) -> TRUE | P13: =AND($B13>=$V$6,$C13>=$W$6,$D13>=$X$6,$E13>=$Y$6,$F13>=$Z$6,$G13>=$AA$6,$H13>=$AB$6,$I13>=$AC$6,$J13>=$AD$6) -> FALSE | Q13: =AND($B13>=$V$7,$C13>=$W$7,$D13>=$X$7,$E13>=$Y$7,$F13>=$Z$7,$G13>=$AA$7,$H13>=$AB$7,$I13>=$AC$7,$J13>=$AD$7) -> FALSE
B14: 1 | C14: 1 | D14: 1 | E14: 1 | F14: 1 | G14: 0 | H14: 0 | I14: 1 | J14: 1 | L14: =AND($B14>=$V$2,$C14>=$W$2,$D14>=$X$2,$E14>=$Y$2,$F14>=$Z$2,$G14>=$AA$2,$H14>=$AB$2,$I14>=$AC$2,$J14>=$AD$2) -> TRUE | M14: =AND($B14>=$V$3,$C14>=$W$3,$D14>=$X$3,$E14>=$Y$3,$F14>=$Z$3,$G14>=$AA$3,$H14>=$AB$3,$I14>=$AC$3,$J14>=$AD$3) -> FALSE | N14: =AND($B14>=$V$4,$C14>=$W$4,$D14>=$X$4,$E14>=$Y$4,$F14>=$Z$4,$G14>=$AA$4,$H14>=$AB$4,$I14>=$AC$4,$J14>=$AD$4) -> FALSE | O14: =AND($B14>=$V$5,$C14>=$W$5,$D14>=$X$5,$E14>=$Y$5,$F14>=$Z$5,$G14>=$AA$5,$H14>=$AB$5,$I14>=$AC$5,$J14>=$AD$5) -> FALSE | P14: =AND($B14>=$V$6,$C14>=$W$6,$D14>=$X$6,$E14>=$Y$6,$F14>=$Z$6,$G14>=$AA$6,$H14>=$AB$6,$I14>=$AC$6,$J14>=$AD$6) -> TRUE | Q14: =AND($B14>=$V$7,$C14>=$W$7,$D14>=$X$7,$E14>=$Y$7,$F14>=$Z$7,$G14>=$AA$7,$H14>=$AB$7,$I14>=$AC$7,$J14>=$AD$7) -> FALSE
B15: 1 | C15: 1 | D15: 1 | E15: 1 | F15: 1 | G15: 0 | H15: 0 | I15: 1 | J15: 0 | L15: =AND($B15>=$V$2,$C15>=$W$2,$D15>=$X$2,$E15>=$Y$2,$F15>=$Z$2,$G15>=$AA$2,$H15>=$AB$2,$I15>=$AC$2,$J15>=$AD$2) -> TRUE | M15: =AND($B15>=$V$3,$C15>=$W$3,$D15>=$X$3,$E15>=$Y$3,$F15>=$Z$3,$G15>=$AA$3,$H15>=$AB$3,$I15>=$AC$3,$J15>=$AD$3) -> FALSE | N15: =AND($B15>=$V$4,$C15>=$W$4,$D15>=$X$4,$E15>=$Y$4,$F15>=$Z$4,$G15>=$AA$4,$H15>=$AB$4,$I15>=$AC$4,$J15>=$AD$4) -> FALSE | O15: =AND($B15>=$V$5,$C15>=$W$5,$D15>=$X$5,$E15>=$Y$5,$F15>=$Z$5,$G15>=$AA$5,$H15>=$AB$5,$I15>=$AC$5,$J15>=$AD$5) -> FALSE | P15: =AND($B15>=$V$6,$C15>=$W$6,$D15>=$X$6,$E15>=$Y$6,$F15>=$Z$6,$G15>=$AA$6,$H15>=$AB$6,$I15>=$AC$6,$J15>=$AD$6) -> TRUE | Q15: =AND($B15>=$V$7,$C15>=$W$7,$D15>=$X$7,$E15>=$Y$7,$F15>=$Z$7,$G15>=$AA$7,$H15>=$AB$7,$I15>=$AC$7,$J15>=$AD$7) -> FALSE
B16: 1 | C16: 1 | D16: 1 | E16: 1 | F16: 1 | G16: 0 | H16: 0 | I16: 0 | J16: 1 | L16: =AND($B16>=$V$2,$C16>=$W$2,$D16>=$X$2,$E16>=$Y$2,$F16>=$Z$2,$G16>=$AA$2,$H16>=$AB$2,$I16>=$AC$2,$J16>=$AD$2) -> TRUE | M16: =AND($B16>=$V$3,$C16>=$W$3,$D16>=$X$3,$E16>=$Y$3,$F16>=$Z$3,$G16>=$AA$3,$H16>=$AB$3,$I16>=$AC$3,$J16>=$AD$3) -> FALSE | N16: =AND($B16>=$V$4,$C16>=$W$4,$D16>=$X$4,$E16>=$Y$4,$F16>=$Z$4,$G16>=$AA$4,$H16>=$AB$4,$I16>=$AC$4,$J16>=$AD$4) -> FALSE | O16: =AND($B16>=$V$5,$C16>=$W$5,$D16>=$X$5,$E16>=$Y$5,$F16>=$Z$5,$G16>=$AA$5,$H16>=$AB$5,$I16>=$AC$5,$J16>=$AD$5) -> FALSE | P16: =AND($B16>=$V$6,$C16>=$W$6,$D16>=$X$6,$E16>=$Y$6,$F16>=$Z$6,$G16>=$AA$6,$H16>=$AB$6,$I16>=$AC$6,$J16>=$AD$6) -> FALSE | Q16: =AND($B16>=$V$7,$C16>=$W$7,$D16>=$X$7,$E16>=$Y$7,$F16>=$Z$7,$G16>=$AA$7,$H16>=$AB$7,$I16>=$AC$7,$J16>=$AD$7) -> FALSE
B17: 1 | C17: 1 | D17: 1 | E17: 1 | F17: 1 | G17: 0 | H17: 0 | I17: 0 | J17: 0 | L17: =AND($B17>=$V$2,$C17>=$W$2,$D17>=$X$2,$E17>=$Y$2,$F17>=$Z$2,$G17>=$AA$2,$H17>=$AB$2,$I17>=$AC$2,$J17>=$AD$2) -> TRUE | M17: =AND($B17>=$V$3,$C17>=$W$3,$D17>=$X$3,$E17>=$Y$3,$F17>=$Z$3,$G17>=$AA$3,$H17>=$AB$3,$I17>=$AC$3,$J17>=$AD$3) -> FALSE | N17: =AND($B17>=$V$4,$C17>=$W$4,$D17>=$X$4,$E17>=$Y$4,$F17>=$Z$4,$G17>=$AA$4,$H17>=$AB$4,$I17>=$AC$4,$J17>=$AD$4) -> FALSE | O17: =AND($B17>=$V$5,$C17>=$W$5,$D17>=$X$5,$E17>=$Y$5,$F17>=$Z$5,$G17>=$AA$5,$H17>=$AB$5,$I17>=$AC$5,$J17>=$AD$5) -> FALSE | P17: =AND($B17>=$V$6,$C17>=$W$6,$D17>=$X$6,$E17>=$Y$6,$F17>=$Z$6,$G17>=$AA$6,$H17>=$AB$6,$I17>=$AC$6,$J17>=$AD$6) -> FALSE | Q17: =AND($B17>=$V$7,$C17>=$W$7,$D17>=$X$7,$E17>=$Y$7,$F17>=$Z$7,$G17>=$AA$7,$H17>=$AB$7,$I17>=$AC$7,$J17>=$AD$7) -> FALSE
B18: 1 | C18: 1 | D18: 1 | E18: 1 | F18: 0 | G18: 1 | H18: 1 | I18: 1 | J18: 1 | L18: =AND($B18>=$V$2,$C18>=$W$2,$D18>=$X$2,$E18>=$Y$2,$F18>=$Z$2,$G18>=$AA$2,$H18>=$AB$2,$I18>=$AC$2,$J18>=$AD$2) -> TRUE | M18: =AND($B18>=$V$3,$C18>=$W$3,$D18>=$X$3,$E18>=$Y$3,$F18>=$Z$3,$G18>=$AA$3,$H18>=$AB$3,$I18>=$AC$3,$J18>=$AD$3) -> FALSE | N18: =AND($B18>=$V$4,$C18>=$W$4,$D18>=$X$4,$E18>=$Y$4,$F18>=$Z$4,$G18>=$AA$4,$H18>=$AB$4,$I18>=$AC$4,$J18>=$AD$4) -> TRUE | O18: =AND($B18>=$V$5,$C18>=$W$5,$D18>=$X$5,$E18>=$Y$5,$F18>=$Z$5,$G18>=$AA$5,$H18>=$AB$5,$I18>=$AC$5,$J18>=$AD$5) -> TRUE | P18: =AND($B18>=$V$6,$C18>=$W$6,$D18>=$X$6,$E18>=$Y$6,$F18>=$Z$6,$G18>=$AA$6,$H18>=$AB$6,$I18>=$AC$6,$J18>=$AD$6) -> FALSE | Q18: =AND($B18>=$V$7,$C18>=$W$7,$D18>=$X$7,$E18>=$Y$7,$F18>=$Z$7,$G18>=$AA$7,$H18>=$AB$7,$I18>=$AC$7,$J18>=$AD$7) -> TRUE
B19: 1 | C19: 1 | D19: 1 | E19: 1 | F19: 0 | G19: 1 | H19: 1 | I19: 1 | J19: 0 | L19: =AND($B19>=$V$2,$C19>=$W$2,$D19>=$X$2,$E19>=$Y$2,$F19>=$Z$2,$G19>=$AA$2,$H19>=$AB$2,$I19>=$AC$2,$J19>=$AD$2) -> TRUE | M19: =AND($B19>=$V$3,$C19>=$W$3,$D19>=$X$3,$E19>=$Y$3,$F19>=$Z$3,$G19>=$AA$3,$H19>=$AB$3,$I19>=$AC$3,$J19>=$AD$3) -> FALSE | N19: =AND($B19>=$V$4,$C19>=$W$4,$D19>=$X$4,$E19>=$Y$4,$F19>=$Z$4,$G19>=$AA$4,$H19>=$AB$4,$I19>=$AC$4,$J19>=$AD$4) -> FALSE | O19: =AND($B19>=$V$5,$C19>=$W$5,$D19>=$X$5,$E19>=$Y$5,$F19>=$Z$5,$G19>=$AA$5,$H19>=$AB$5,$I19>=$AC$5,$J19>=$AD$5) -> TRUE | P19: =AND($B19>=$V$6,$C19>=$W$6,$D19>=$X$6,$E19>=$Y$6,$F19>=$Z$6,$G19>=$AA$6,$H19>=$AB$6,$I19>=$AC$6,$J19>=$AD$6) -> FALSE | Q19: =AND($B19>=$V$7,$C19>=$W$7,$D19>=$X$7,$E19>=$Y$7,$F19>=$Z$7,$G19>=$AA$7,$H19>=$AB$7,$I19>=$AC$7,$J19>=$AD$7) -> FALSE
... B513: 0 | C513: 0 | D513: 0 | E513: 0 | F513: 0 | G513: 0 | H513: 0 | I513: 0 | J513: 0 | L513: =AND($B513>=$V$2,$C513>=$W$2,$D513>=$X$2,$E513>=$Y$2,$F513>=$Z$2,$G513>=$AA$2,$H513>=$AB$2,$I513>=$AC$2,$J513>=$AD$2) -> FALSE | M513: =AND($B513>=$V$3,$C513>=$W$3,$D513>=$X$3,$E513>=$Y$3,$F513>=$Z$3,$G513>=$AA$3,$H513>=$AB$3,$I513>=$AC$3,$J513>=$AD$3) -> FALSE | N513: =AND($B513>=$V$4,$C513>=$W$4,$D513>=$X$4,$E513>=$Y$4,$F513>=$Z$4,$G513>=$AA$4,$H513>=$AB$4,$I513>=$AC$4,$J513>=$AD$4) -> FALSE | O513: =AND($B513>=$V$5,$C513>=$W$5,$D513>=$X$5,$E513>=$Y$5,$F513>=$Z$5,$G513>=$AA$5,$H513>=$AB$5,$I513>=$AC$5,$J513>=$AD$5) -> FALSE | P513: =AND($B513>=$V$6,$C513>=$W$6,$D513>=$X$6,$E513>=$Y$6,$F513>=$Z$6,$G513>=$AA$6,$H513>=$AB$6,$I513>=$AC$6,$J513>=$AD$6) -> FALSE | Q513: =AND($B513>=$V$7,$C513>=$W$7,$D513>=$X$7,$E513>=$Y$7,$F513>=$Z$7,$G513>=$AA$7,$H513>=$AB$7,$I513>=$AC$7,$J513>=$AD$7) -> FALSE

Sheet ball combine if wild
A1: LC | B1: MC | C1: RC | D1: UR | E1: MR | F1: DR | H1: 1 | I1: 2 | J1: 3 | K1: 4 | L1: 5 | M1: 6 | N1: 7 | O1: 8 | P1: 9 | Q1: slot | R1: line | S1: 10 | T1: 11 | U1: 12 | V1: 13 | W1: 14
A2: 0 | B2: 0 | C2: 0 | D2: 0 | E2: 0 | F2: 0 | H2: =IF(OR(A2=1,D2=1),1,0) -> 0 | I2: =IF(OR(B2=1,D2=1),1,0) -> 0 | J2: =IF(OR(C2=1,D2=1),1,0) -> 0 | K2: =IF(OR(A2=1,E2=1),1,0) -> 0 | L2: =IF(OR(B2=1,E2=1),1,0) -> 0 | M2: =IF(OR(C2=1,E2=1),1,0) -> 0 | N2: =IF(OR(A2=1,F2=1),1,0) -> 0 | O2: =IF(OR(B2=1,F2=1),1,0) -> 0 | P2: =IF(OR(C2=1,F2=1),1,0) -> 0 | Q2: =SUM(H2:P2) -> 0 | R2: =SUM(A2:F2) -> 0 | S2: =COMBIN(30,S$1-$Q2) -> 30045015 | T2: =COMBIN(30,T$1-$Q2) -> 54627300 | U2: =COMBIN(30,U$1-$Q2) -> 86493225 | V2: =COMBIN(30,V$1-$Q2) -> 119759850 | W2: =COMBIN(30,W$1-$Q2) -> 145422675
A3: 1 | B3: 0 | C3: 0 | D3: 0 | E3: 0 | F3: 0 | H3: =IF(OR(A3=1,D3=1),1,0) -> 1 | I3: =IF(OR(B3=1,D3=1),1,0) -> 0 | J3: =IF(OR(C3=1,D3=1),1,0) -> 0 | K3: =IF(OR(A3=1,E3=1),1,0) -> 1 | L3: =IF(OR(B3=1,E3=1),1,0) -> 0 | M3: =IF(OR(C3=1,E3=1),1,0) -> 0 | N3: =IF(OR(A3=1,F3=1),1,0) -> 1 | O3: =IF(OR(B3=1,F3=1),1,0) -> 0 | P3: =IF(OR(C3=1,F3=1),1,0) -> 0 | Q3: =SUM(H3:P3) -> 3 | R3: =SUM(A3:F3) -> 1 | S3: =COMBIN(30-$Q3,S$1-$Q3) -> 888030 | T3: =COMBIN(30-$Q3,T$1-$Q3) -> 2220075 | U3: =COMBIN(30-$Q3,U$1-$Q3) -> 4686825 | V3: =COMBIN(30-$Q3,V$1-$Q3) -> 8436285 | W3: =COMBIN(30-$Q3,W$1-$Q3) -> 13037895
A4: 0 | B4: 1 | C4: 0 | D4: 0 | E4: 0 | F4: 0 | H4: =IF(OR(A4=1,D4=1),1,0) -> 0 | I4: =IF(OR(B4=1,D4=1),1,0) -> 1 | J4: =IF(OR(C4=1,D4=1),1,0) -> 0 | K4: =IF(OR(A4=1,E4=1),1,0) -> 0 | L4: =IF(OR(B4=1,E4=1),1,0) -> 1 | M4: =IF(OR(C4=1,E4=1),1,0) -> 0 | N4: =IF(OR(A4=1,F4=1),1,0) -> 0 | O4: =IF(OR(B4=1,F4=1),1,0) -> 1 | P4: =IF(OR(C4=1,F4=1),1,0) -> 0 | Q4: =SUM(H4:P4) -> 3 | R4: =SUM(A4:F4) -> 1 | S4: =COMBIN(30-$Q4,S$1-$Q4) -> 888030 | T4: =COMBIN(30-$Q4,T$1-$Q4) -> 2220075 | U4: =COMBIN(30-$Q4,U$1-$Q4) -> 4686825 | V4: =COMBIN(30-$Q4,V$1-$Q4) -> 8436285 | W4: =COMBIN(30-$Q4,W$1-$Q4) -> 13037895
A5: 0 | B5: 0 | C5: 0 | D5: 1 | E5: 0 | F5: 0 | H5: =IF(OR(A5=1,D5=1),1,0) -> 1 | I5: =IF(OR(B5=1,D5=1),1,0) -> 1 | J5: =IF(OR(C5=1,D5=1),1,0) -> 1 | K5: =IF(OR(A5=1,E5=1),1,0) -> 0 | L5: =IF(OR(B5=1,E5=1),1,0) -> 0 | M5: =IF(OR(C5=1,E5=1),1,0) -> 0 | N5: =IF(OR(A5=1,F5=1),1,0) -> 0 | O5: =IF(OR(B5=1,F5=1),1,0) -> 0 | P5: =IF(OR(C5=1,F5=1),1,0) -> 0 | Q5: =SUM(H5:P5) -> 3 | R5: =SUM(A5:F5) -> 1 | S5: =COMBIN(30-$Q5,S$1-$Q5) -> 888030 | T5: =COMBIN(30-$Q5,T$1-$Q5) -> 2220075 | U5: =COMBIN(30-$Q5,U$1-$Q5) -> 4686825 | V5: =COMBIN(30-$Q5,V$1-$Q5) -> 8436285 | W5: =COMBIN(30-$Q5,W$1-$Q5) -> 13037895
A6: 0 | B6: 0 | C6: 0 | D6: 0 | E6: 1 | F6: 0 | H6: =IF(OR(A6=1,D6=1),1,0) -> 0 | I6: =IF(OR(B6=1,D6=1),1,0) -> 0 | J6: =IF(OR(C6=1,D6=1),1,0) -> 0 | K6: =IF(OR(A6=1,E6=1),1,0) -> 1 | L6: =IF(OR(B6=1,E6=1),1,0) -> 1 | M6: =IF(OR(C6=1,E6=1),1,0) -> 1 | N6: =IF(OR(A6=1,F6=1),1,0) -> 0 | O6: =IF(OR(B6=1,F6=1),1,0) -> 0 | P6: =IF(OR(C6=1,F6=1),1,0) -> 0 | Q6: =SUM(H6:P6) -> 3 | R6: =SUM(A6:F6) -> 1 | S6: =COMBIN(30-$Q6,S$1-$Q6) -> 888030 | T6: =COMBIN(30-$Q6,T$1-$Q6) -> 2220075 | U6: =COMBIN(30-$Q6,U$1-$Q6) -> 4686825 | V6: =COMBIN(30-$Q6,V$1-$Q6) -> 8436285 | W6: =COMBIN(30-$Q6,W$1-$Q6) -> 13037895
A7: 0 | B7: 0 | C7: 1 | D7: 0 | E7: 0 | F7: 0 | H7: =IF(OR(A7=1,D7=1),1,0) -> 0 | I7: =IF(OR(B7=1,D7=1),1,0) -> 0 | J7: =IF(OR(C7=1,D7=1),1,0) -> 1 | K7: =IF(OR(A7=1,E7=1),1,0) -> 0 | L7: =IF(OR(B7=1,E7=1),1,0) -> 0 | M7: =IF(OR(C7=1,E7=1),1,0) -> 1 | N7: =IF(OR(A7=1,F7=1),1,0) -> 0 | O7: =IF(OR(B7=1,F7=1),1,0) -> 0 | P7: =IF(OR(C7=1,F7=1),1,0) -> 1 | Q7: =SUM(H7:P7) -> 3 | R7: =SUM(A7:F7) -> 1 | S7: =COMBIN(30-$Q7,S$1-$Q7) -> 888030 | T7: =COMBIN(30-$Q7,T$1-$Q7) -> 2220075 | U7: =COMBIN(30-$Q7,U$1-$Q7) -> 4686825 | V7: =COMBIN(30-$Q7,V$1-$Q7) -> 8436285 | W7: =COMBIN(30-$Q7,W$1-$Q7) -> 13037895
A8: 0 | B8: 0 | C8: 0 | D8: 0 | E8: 0 | F8: 1 | H8: =IF(OR(A8=1,D8=1),1,0) -> 0 | I8: =IF(OR(B8=1,D8=1),1,0) -> 0 | J8: =IF(OR(C8=1,D8=1),1,0) -> 0 | K8: =IF(OR(A8=1,E8=1),1,0) -> 0 | L8: =IF(OR(B8=1,E8=1),1,0) -> 0 | M8: =IF(OR(C8=1,E8=1),1,0) -> 0 | N8: =IF(OR(A8=1,F8=1),1,0) -> 1 | O8: =IF(OR(B8=1,F8=1),1,0) -> 1 | P8: =IF(OR(C8=1,F8=1),1,0) -> 1 | Q8: =SUM(H8:P8) -> 3 | R8: =SUM(A8:F8) -> 1 | S8: =COMBIN(30-$Q8,S$1-$Q8) -> 888030 | T8: =COMBIN(30-$Q8,T$1-$Q8) -> 2220075 | U8: =COMBIN(30-$Q8,U$1-$Q8) -> 4686825 | V8: =COMBIN(30-$Q8,V$1-$Q8) -> 8436285 | W8: =COMBIN(30-$Q8,W$1-$Q8) -> 13037895
A9: 1 | B9: 0 | C9: 0 | D9: 1 | E9: 0 | F9: 0 | H9: =IF(OR(A9=1,D9=1),1,0) -> 1 | I9: =IF(OR(B9=1,D9=1),1,0) -> 1 | J9: =IF(OR(C9=1,D9=1),1,0) -> 1 | K9: =IF(OR(A9=1,E9=1),1,0) -> 1 | L9: =IF(OR(B9=1,E9=1),1,0) -> 0 | M9: =IF(OR(C9=1,E9=1),1,0) -> 0 | N9: =IF(OR(A9=1,F9=1),1,0) -> 1 | O9: =IF(OR(B9=1,F9=1),1,0) -> 0 | P9: =IF(OR(C9=1,F9=1),1,0) -> 0 | Q9: =SUM(H9:P9) -> 5 | R9: =SUM(A9:F9) -> 2 | S9: =COMBIN(30-$Q9,S$1-$Q9) -> 53130 | T9: =COMBIN(30-$Q9,T$1-$Q9) -> 177100 | U9: =COMBIN(30-$Q9,U$1-$Q9) -> 480700 | V9: =COMBIN(30-$Q9,V$1-$Q9) -> 1081575 | W9: =COMBIN(30-$Q9,W$1-$Q9) -> 2042975
A10: 1 | B10: 0 | C10: 0 | D10: 0 | E10: 1 | F10: 0 | H10: =IF(OR(A10=1,D10=1),1,0) -> 1 | I10: =IF(OR(B10=1,D10=1),1,0) -> 0 | J10: =IF(OR(C10=1,D10=1),1,0) -> 0 | K10: =IF(OR(A10=1,E10=1),1,0) -> 1 | L10: =IF(OR(B10=1,E10=1),1,0) -> 1 | M10: =IF(OR(C10=1,E10=1),1,0) -> 1 | N10: =IF(OR(A10=1,F10=1),1,0) -> 1 | O10: =IF(OR(B10=1,F10=1),1,0) -> 0 | P10: =IF(OR(C10=1,F10=1),1,0) -> 0 | Q10: =SUM(H10:P10) -> 5 | R10: =SUM(A10:F10) -> 2 | S10: =COMBIN(30-$Q10,S$1-$Q10) -> 53130 | T10: =COMBIN(30-$Q10,T$1-$Q10) -> 177100 | U10: =COMBIN(30-$Q10,U$1-$Q10) -> 480700 | V10: =COMBIN(30-$Q10,V$1-$Q10) -> 1081575 | W10: =COMBIN(30-$Q10,W$1-$Q10) -> 2042975
A11: 1 | B11: 0 | C11: 0 | D11: 0 | E11: 0 | F11: 1 | H11: =IF(OR(A11=1,D11=1),1,0) -> 1 | I11: =IF(OR(B11=1,D11=1),1,0) -> 0 | J11: =IF(OR(C11=1,D11=1),1,0) -> 0 | K11: =IF(OR(A11=1,E11=1),1,0) -> 1 | L11: =IF(OR(B11=1,E11=1),1,0) -> 0 | M11: =IF(OR(C11=1,E11=1),1,0) -> 0 | N11: =IF(OR(A11=1,F11=1),1,0) -> 1 | O11: =IF(OR(B11=1,F11=1),1,0) -> 1 | P11: =IF(OR(C11=1,F11=1),1,0) -> 1 | Q11: =SUM(H11:P11) -> 5 | R11: =SUM(A11:F11) -> 2 | S11: =COMBIN(30-$Q11,S$1-$Q11) -> 53130 | T11: =COMBIN(30-$Q11,T$1-$Q11) -> 177100 | U11: =COMBIN(30-$Q11,U$1-$Q11) -> 480700 | V11: =COMBIN(30-$Q11,V$1-$Q11) -> 1081575 | W11: =COMBIN(30-$Q11,W$1-$Q11) -> 2042975
A12: 0 | B12: 1 | C12: 0 | D12: 1 | E12: 0 | F12: 0 | H12: =IF(OR(A12=1,D12=1),1,0) -> 1 | I12: =IF(OR(B12=1,D12=1),1,0) -> 1 | J12: =IF(OR(C12=1,D12=1),1,0) -> 1 | K12: =IF(OR(A12=1,E12=1),1,0) -> 0 | L12: =IF(OR(B12=1,E12=1),1,0) -> 1 | M12: =IF(OR(C12=1,E12=1),1,0) -> 0 | N12: =IF(OR(A12=1,F12=1),1,0) -> 0 | O12: =IF(OR(B12=1,F12=1),1,0) -> 1 | P12: =IF(OR(C12=1,F12=1),1,0) -> 0 | Q12: =SUM(H12:P12) -> 5 | R12: =SUM(A12:F12) -> 2 | S12: =COMBIN(30-$Q12,S$1-$Q12) -> 53130 | T12: =COMBIN(30-$Q12,T$1-$Q12) -> 177100 | U12: =COMBIN(30-$Q12,U$1-$Q12) -> 480700 | V12: =COMBIN(30-$Q12,V$1-$Q12) -> 1081575 | W12: =COMBIN(30-$Q12,W$1-$Q12) -> 2042975
A13: 0 | B13: 1 | C13: 0 | D13: 0 | E13: 1 | F13: 0 | H13: =IF(OR(A13=1,D13=1),1,0) -> 0 | I13: =IF(OR(B13=1,D13=1),1,0) -> 1 | J13: =IF(OR(C13=1,D13=1),1,0) -> 0 | K13: =IF(OR(A13=1,E13=1),1,0) -> 1 | L13: =IF(OR(B13=1,E13=1),1,0) -> 1 | M13: =IF(OR(C13=1,E13=1),1,0) -> 1 | N13: =IF(OR(A13=1,F13=1),1,0) -> 0 | O13: =IF(OR(B13=1,F13=1),1,0) -> 1 | P13: =IF(OR(C13=1,F13=1),1,0) -> 0 | Q13: =SUM(H13:P13) -> 5 | R13: =SUM(A13:F13) -> 2 | S13: =COMBIN(30-$Q13,S$1-$Q13) -> 53130 | T13: =COMBIN(30-$Q13,T$1-$Q13) -> 177100 | U13: =COMBIN(30-$Q13,U$1-$Q13) -> 480700 | V13: =COMBIN(30-$Q13,V$1-$Q13) -> 1081575 | W13: =COMBIN(30-$Q13,W$1-$Q13) -> 2042975
A14: 0 | B14: 0 | C14: 1 | D14: 1 | E14: 0 | F14: 0 | H14: =IF(OR(A14=1,D14=1),1,0) -> 1 | I14: =IF(OR(B14=1,D14=1),1,0) -> 1 | J14: =IF(OR(C14=1,D14=1),1,0) -> 1 | K14: =IF(OR(A14=1,E14=1),1,0) -> 0 | L14: =IF(OR(B14=1,E14=1),1,0) -> 0 | M14: =IF(OR(C14=1,E14=1),1,0) -> 1 | N14: =IF(OR(A14=1,F14=1),1,0) -> 0 | O14: =IF(OR(B14=1,F14=1),1,0) -> 0 | P14: =IF(OR(C14=1,F14=1),1,0) -> 1 | Q14: =SUM(H14:P14) -> 5 | R14: =SUM(A14:F14) -> 2 | S14: =COMBIN(30-$Q14,S$1-$Q14) -> 53130 | T14: =COMBIN(30-$Q14,T$1-$Q14) -> 177100 | U14: =COMBIN(30-$Q14,U$1-$Q14) -> 480700 | V14: =COMBIN(30-$Q14,V$1-$Q14) -> 1081575 | W14: =COMBIN(30-$Q14,W$1-$Q14) -> 2042975
... A51: 1 | B51: 1 | C51: 1 | D51: 1 | E51: 1 | F51: 1 | H51: =IF(OR(A51=1,D51=1),1,0) -> 1 | I51: =IF(OR(B51=1,D51=1),1,0) -> 1 | J51: =IF(OR(C51=1,D51=1),1,0) -> 1 | K51: =IF(OR(A51=1,E51=1),1,0) -> 1 | L51: =IF(OR(B51=1,E51=1),1,0) -> 1 | M51: =IF(OR(C51=1,E51=1),1,0) -> 1 | N51: =IF(OR(A51=1,F51=1),1,0) -> 1 | O51: =IF(OR(B51=1,F51=1),1,0) -> 1 | P51: =IF(OR(C51=1,F51=1),1,0) -> 1 | Q51: =SUM(H51:P51) -> 9 | R51: =SUM(A51:F51) -> 6 | S51: =COMBIN(30-$Q51,S$1-$Q51) -> 21 | T51: =COMBIN(30-$Q51,T$1-$Q51) -> 210 | U51: =COMBIN(30-$Q51,U$1-$Q51) -> 1330 | V51: =COMBIN(30-$Q51,V$1-$Q51) -> 5985 | W51: =COMBIN(30-$Q51,W$1-$Q51) -> 20349

Sheet ball combine if not wild
A1: LC | B1: MC | C1: RC | D1: UR | E1: MR | F1: DR | H1: 1 | I1: 2 | J1: 3 | K1: 4 | L1: 5 | M1: 6 | N1: 7 | O1: 8 | P1: 9 | Q1: slot | R1: line | S1: 9
A2: 0 | B2: 0 | C2: 0 | D2: 0 | E2: 0 | F2: 0 | H2: =IF(OR(A2=1,D2=1),1,0) -> 0 | I2: =IF(OR(B2=1,D2=1),1,0) -> 0 | J2: =IF(OR(C2=1,D2=1),1,0) -> 0 | K2: =IF(OR(A2=1,E2=1),1,0) -> 0 | L2: =IF(OR(B2=1,E2=1),1,0) -> 0 | M2: =IF(OR(C2=1,E2=1),1,0) -> 0 | N2: =IF(OR(A2=1,F2=1),1,0) -> 0 | O2: =IF(OR(B2=1,F2=1),1,0) -> 0 | P2: =IF(OR(C2=1,F2=1),1,0) -> 0 | Q2: =SUM(H2:P2) -> 0 | R2: =SUM(A2:F2) -> 0 | S2: =COMBIN(30,9) -> 14307150
A3: 1 | B3: 0 | C3: 0 | D3: 0 | E3: 0 | F3: 0 | H3: =IF(OR(A3=1,D3=1),1,0) -> 1 | I3: =IF(OR(B3=1,D3=1),1,0) -> 0 | J3: =IF(OR(C3=1,D3=1),1,0) -> 0 | K3: =IF(OR(A3=1,E3=1),1,0) -> 1 | L3: =IF(OR(B3=1,E3=1),1,0) -> 0 | M3: =IF(OR(C3=1,E3=1),1,0) -> 0 | N3: =IF(OR(A3=1,F3=1),1,0) -> 1 | O3: =IF(OR(B3=1,F3=1),1,0) -> 0 | P3: =IF(OR(C3=1,F3=1),1,0) -> 0 | Q3: =SUM(H3:P3) -> 3 | R3: =SUM(A3:F3) -> 1 | S3: =COMBIN(30-$Q3,$S$1-$Q3) -> 296010
A4: 0 | B4: 1 | C4: 0 | D4: 0 | E4: 0 | F4: 0 | H4: =IF(OR(A4=1,D4=1),1,0) -> 0 | I4: =IF(OR(B4=1,D4=1),1,0) -> 1 | J4: =IF(OR(C4=1,D4=1),1,0) -> 0 | K4: =IF(OR(A4=1,E4=1),1,0) -> 0 | L4: =IF(OR(B4=1,E4=1),1,0) -> 1 | M4: =IF(OR(C4=1,E4=1),1,0) -> 0 | N4: =IF(OR(A4=1,F4=1),1,0) -> 0 | O4: =IF(OR(B4=1,F4=1),1,0) -> 1 | P4: =IF(OR(C4=1,F4=1),1,0) -> 0 | Q4: =SUM(H4:P4) -> 3 | R4: =SUM(A4:F4) -> 1 | S4: =COMBIN(30-$Q4,$S$1-$Q4) -> 296010
A5: 0 | B5: 0 | C5: 0 | D5: 1 | E5: 0 | F5: 0 | H5: =IF(OR(A5=1,D5=1),1,0) -> 1 | I5: =IF(OR(B5=1,D5=1),1,0) -> 1 | J5: =IF(OR(C5=1,D5=1),1,0) -> 1 | K5: =IF(OR(A5=1,E5=1),1,0) -> 0 | L5: =IF(OR(B5=1,E5=1),1,0) -> 0 | M5: =IF(OR(C5=1,E5=1),1,0) -> 0 | N5: =IF(OR(A5=1,F5=1),1,0) -> 0 | O5: =IF(OR(B5=1,F5=1),1,0) -> 0 | P5: =IF(OR(C5=1,F5=1),1,0) -> 0 | Q5: =SUM(H5:P5) -> 3 | R5: =SUM(A5:F5) -> 1 | S5: =COMBIN(30-$Q5,$S$1-$Q5) -> 296010
A6: 0 | B6: 0 | C6: 0 | D6: 0 | E6: 1 | F6: 0 | H6: =IF(OR(A6=1,D6=1),1,0) -> 0 | I6: =IF(OR(B6=1,D6=1),1,0) -> 0 | J6: =IF(OR(C6=1,D6=1),1,0) -> 0 | K6: =IF(OR(A6=1,E6=1),1,0) -> 1 | L6: =IF(OR(B6=1,E6=1),1,0) -> 1 | M6: =IF(OR(C6=1,E6=1),1,0) -> 1 | N6: =IF(OR(A6=1,F6=1),1,0) -> 0 | O6: =IF(OR(B6=1,F6=1),1,0) -> 0 | P6: =IF(OR(C6=1,F6=1),1,0) -> 0 | Q6: =SUM(H6:P6) -> 3 | R6: =SUM(A6:F6) -> 1 | S6: =COMBIN(30-$Q6,$S$1-$Q6) -> 296010
A7: 0 | B7: 0 | C7: 1 | D7: 0 | E7: 0 | F7: 0 | H7: =IF(OR(A7=1,D7=1),1,0) -> 0 | I7: =IF(OR(B7=1,D7=1),1,0) -> 0 | J7: =IF(OR(C7=1,D7=1),1,0) -> 1 | K7: =IF(OR(A7=1,E7=1),1,0) -> 0 | L7: =IF(OR(B7=1,E7=1),1,0) -> 0 | M7: =IF(OR(C7=1,E7=1),1,0) -> 1 | N7: =IF(OR(A7=1,F7=1),1,0) -> 0 | O7: =IF(OR(B7=1,F7=1),1,0) -> 0 | P7: =IF(OR(C7=1,F7=1),1,0) -> 1 | Q7: =SUM(H7:P7) -> 3 | R7: =SUM(A7:F7) -> 1 | S7: =COMBIN(30-$Q7,$S$1-$Q7) -> 296010
A8: 0 | B8: 0 | C8: 0 | D8: 0 | E8: 0 | F8: 1 | H8: =IF(OR(A8=1,D8=1),1,0) -> 0 | I8: =IF(OR(B8=1,D8=1),1,0) -> 0 | J8: =IF(OR(C8=1,D8=1),1,0) -> 0 | K8: =IF(OR(A8=1,E8=1),1,0) -> 0 | L8: =IF(OR(B8=1,E8=1),1,0) -> 0 | M8: =IF(OR(C8=1,E8=1),1,0) -> 0 | N8: =IF(OR(A8=1,F8=1),1,0) -> 1 | O8: =IF(OR(B8=1,F8=1),1,0) -> 1 | P8: =IF(OR(C8=1,F8=1),1,0) -> 1 | Q8: =SUM(H8:P8) -> 3 | R8: =SUM(A8:F8) -> 1 | S8: =COMBIN(30-$Q8,$S$1-$Q8) -> 296010
A9: 1 | B9: 0 | C9: 0 | D9: 1 | E9: 0 | F9: 0 | H9: =IF(OR(A9=1,D9=1),1,0) -> 1 | I9: =IF(OR(B9=1,D9=1),1,0) -> 1 | J9: =IF(OR(C9=1,D9=1),1,0) -> 1 | K9: =IF(OR(A9=1,E9=1),1,0) -> 1 | L9: =IF(OR(B9=1,E9=1),1,0) -> 0 | M9: =IF(OR(C9=1,E9=1),1,0) -> 0 | N9: =IF(OR(A9=1,F9=1),1,0) -> 1 | O9: =IF(OR(B9=1,F9=1),1,0) -> 0 | P9: =IF(OR(C9=1,F9=1),1,0) -> 0 | Q9: =SUM(H9:P9) -> 5 | R9: =SUM(A9:F9) -> 2 | S9: =COMBIN(30-$Q9,$S$1-$Q9) -> 12650
A10: 1 | B10: 0 | C10: 0 | D10: 0 | E10: 1 | F10: 0 | H10: =IF(OR(A10=1,D10=1),1,0) -> 1 | I10: =IF(OR(B10=1,D10=1),1,0) -> 0 | J10: =IF(OR(C10=1,D10=1),1,0) -> 0 | K10: =IF(OR(A10=1,E10=1),1,0) -> 1 | L10: =IF(OR(B10=1,E10=1),1,0) -> 1 | M10: =IF(OR(C10=1,E10=1),1,0) -> 1 | N10: =IF(OR(A10=1,F10=1),1,0) -> 1 | O10: =IF(OR(B10=1,F10=1),1,0) -> 0 | P10: =IF(OR(C10=1,F10=1),1,0) -> 0 | Q10: =SUM(H10:P10) -> 5 | R10: =SUM(A10:F10) -> 2 | S10: =COMBIN(30-$Q10,$S$1-$Q10) -> 12650
A11: 1 | B11: 0 | C11: 0 | D11: 0 | E11: 0 | F11: 1 | H11: =IF(OR(A11=1,D11=1),1,0) -> 1 | I11: =IF(OR(B11=1,D11=1),1,0) -> 0 | J11: =IF(OR(C11=1,D11=1),1,0) -> 0 | K11: =IF(OR(A11=1,E11=1),1,0) -> 1 | L11: =IF(OR(B11=1,E11=1),1,0) -> 0 | M11: =IF(OR(C11=1,E11=1),1,0) -> 0 | N11: =IF(OR(A11=1,F11=1),1,0) -> 1 | O11: =IF(OR(B11=1,F11=1),1,0) -> 1 | P11: =IF(OR(C11=1,F11=1),1,0) -> 1 | Q11: =SUM(H11:P11) -> 5 | R11: =SUM(A11:F11) -> 2 | S11: =COMBIN(30-$Q11,$S$1-$Q11) -> 12650
A12: 0 | B12: 1 | C12: 0 | D12: 1 | E12: 0 | F12: 0 | H12: =IF(OR(A12=1,D12=1),1,0) -> 1 | I12: =IF(OR(B12=1,D12=1),1,0) -> 1 | J12: =IF(OR(C12=1,D12=1),1,0) -> 1 | K12: =IF(OR(A12=1,E12=1),1,0) -> 0 | L12: =IF(OR(B12=1,E12=1),1,0) -> 1 | M12: =IF(OR(C12=1,E12=1),1,0) -> 0 | N12: =IF(OR(A12=1,F12=1),1,0) -> 0 | O12: =IF(OR(B12=1,F12=1),1,0) -> 1 | P12: =IF(OR(C12=1,F12=1),1,0) -> 0 | Q12: =SUM(H12:P12) -> 5 | R12: =SUM(A12:F12) -> 2 | S12: =COMBIN(30-$Q12,$S$1-$Q12) -> 12650
A13: 0 | B13: 1 | C13: 0 | D13: 0 | E13: 1 | F13: 0 | H13: =IF(OR(A13=1,D13=1),1,0) -> 0 | I13: =IF(OR(B13=1,D13=1),1,0) -> 1 | J13: =IF(OR(C13=1,D13=1),1,0) -> 0 | K13: =IF(OR(A13=1,E13=1),1,0) -> 1 | L13: =IF(OR(B13=1,E13=1),1,0) -> 1 | M13: =IF(OR(C13=1,E13=1),1,0) -> 1 | N13: =IF(OR(A13=1,F13=1),1,0) -> 0 | O13: =IF(OR(B13=1,F13=1),1,0) -> 1 | P13: =IF(OR(C13=1,F13=1),1,0) -> 0 | Q13: =SUM(H13:P13) -> 5 | R13: =SUM(A13:F13) -> 2 | S13: =COMBIN(30-$Q13,$S$1-$Q13) -> 12650
A14: 0 | B14: 0 | C14: 1 | D14: 1 | E14: 0 | F14: 0 | H14: =IF(OR(A14=1,D14=1),1,0) -> 1 | I14: =IF(OR(B14=1,D14=1),1,0) -> 1 | J14: =IF(OR(C14=1,D14=1),1,0) -> 1 | K14: =IF(OR(A14=1,E14=1),1,0) -> 0 | L14: =IF(OR(B14=1,E14=1),1,0) -> 0 | M14: =IF(OR(C14=1,E14=1),1,0) -> 1 | N14: =IF(OR(A14=1,F14=1),1,0) -> 0 | O14: =IF(OR(B14=1,F14=1),1,0) -> 0 | P14: =IF(OR(C14=1,F14=1),1,0) -> 1 | Q14: =SUM(H14:P14) -> 5 | R14: =SUM(A14:F14) -> 2 | S14: =COMBIN(30-$Q14,$S$1-$Q14) -> 12650
... A51: 1 | B51: 1 | C51: 1 | D51: 1 | E51: 1 | F51: 1 | H51: =IF(OR(A51=1,D51=1),1,0) -> 1 | I51: =IF(OR(B51=1,D51=1),1,0) -> 1 | J51: =IF(OR(C51=1,D51=1),1,0) -> 1 | K51: =IF(OR(A51=1,E51=1),1,0) -> 1 | L51: =IF(OR(B51=1,E51=1),1,0) -> 1 | M51: =IF(OR(C51=1,E51=1),1,0) -> 1 | N51: =IF(OR(A51=1,F51=1),1,0) -> 1 | O51: =IF(OR(B51=1,F51=1),1,0) -> 1 | P51: =IF(OR(C51=1,F51=1),1,0) -> 1 | Q51: =SUM(H51:P51) -> 9 | R51: =SUM(A51:F51) -> 6 | S51: =COMBIN(30-$Q51,$S$1-$Q51) -> 1

Sheet rtp before multiplier
A1: choose | B1: slot | C1: line | D1: combinations | E1: original combination | F1: 扣掉得分更高的重复可能 | G1: 总可能 | H1: 几率 | I1: 倍率 | J1: RTP
A2: 9 | B2: 0 | C2: 0 | D2: =COUNTIFS('ball combine if not wild'!Q:Q,"="&'rtp before multiplier'!B2,'ball combine if not wild'!R:R,"="&'rtp before multiplier'!C2) -> 1 | E2: =SUMIFS('ball combine if not wild'!S:S,'ball combine if not wild'!Q:Q,"="&'rtp before multiplier'!B2,'ball combine if not wild'!R:R,"="&'rtp before multiplier'!C2)/D2 -> 14307150 | G2: =E2-SUM(G3:G8) -> 12652727 | H2: =G2/$E$2 -> 0.8843639
A3: 9 | B3: 3 | C3: 1 | D3: =COUNTIFS('ball combine if not wild'!Q:Q,"="&'rtp before multiplier'!B3,'ball combine if not wild'!R:R,"="&'rtp before multiplier'!C3) -> 6 | E3: =SUMIFS('ball combine if not wild'!S:S,'ball combine if not wild'!Q:Q,"="&'rtp before multiplier'!B3,'ball combine if not wild'!R:R,"="&'rtp before multiplier'!C3)/D3 -> 296010 | F3: =E3-F4*3-F5*2-F6*9-F7*6-E8 -> 256158 | G3: =F3*D3 -> 1536948 | H3: =G3/$E$2 -> 0.10742517 | I3: 2 | J3: =H3*I3 -> 0.21485034 | P3: 9 | Q3: 10 | R3: 11 | S3: 12 | T3: 13
A4: 9 | B4: 5 | C4: 2 | D4: =COUNTIFS('ball combine if not wild'!Q:Q,"="&'rtp before multiplier'!B4,'ball combine if not wild'!R:R,"="&'rtp before multiplier'!C4) -> 9 | E4: =SUMIFS('ball combine if not wild'!S:S,'ball combine if not wild'!Q:Q,"="&'rtp before multiplier'!B4,'ball combine if not wild'!R:R,"="&'rtp before multiplier'!C4)/D4 -> 12650 | F4: =E4-F6*4-F7*4-E8 -> 11725 | G4: =F4*D4 -> 105525 | H4: =G4/$E$2 -> 0.0073756828 | I4: 5 | J4: =H4*I4 -> 0.036878414 | O4: probability | P4: 0.70967742 | Q4: 0.087096774 | R4: 0.11612903 | S4: 0.058064516 | T4: 0.029032258
A5: 9 | B5: 6 | C5: 2 | D5: =COUNTIFS('ball combine if not wild'!Q:Q,"="&'rtp before multiplier'!B5,'ball combine if not wild'!R:R,"="&'rtp before multiplier'!C5) -> 6 | E5: =SUMIFS('ball combine if not wild'!S:S,'ball combine if not wild'!Q:Q,"="&'rtp before multiplier'!B5,'ball combine if not wild'!R:R,"="&'rtp before multiplier'!C5)/D5 -> 2024 | F5: =E5-F6*3-F7*3-E8 -> 1330 | G5: =F5*D5 -> 7980 | H5: =G5/$E$2 -> 0.00055776308 | I5: 5 | J5: =H5*I5 -> 0.0027888154 | O5: 1 | P5: {=INDEX($H:$H,MATCH(1,($A:$A=P$3)*($C:$C=$O5),0))} -> 0.10742517 | Q5: {=INDEX($H:$H,MATCH(1,($A:$A=Q$3)*($C:$C=$O5),0))} -> 0.14417606 | R5: {=INDEX($H:$H,MATCH(1,($A:$A=R$3)*($C:$C=$O5),0))} -> 0.18391156 | S5: {=INDEX($H:$H,MATCH(1,($A:$A=S$3)*($C:$C=$O5),0))} -> 0.22446711 | T5: {=INDEX($H:$H,MATCH(1,($A:$A=T$3)*($C:$C=$O5),0))} -> 0.26331977
A6: 9 | B6: 7 | C6: 3 | D6: =COUNTIFS('ball combine if not wild'!Q:Q,"="&'rtp before multiplier'!B6,'ball combine if not wild'!R:R,"="&'rtp before multiplier'!C6) -> 18 | E6: =SUMIFS('ball combine if not wild'!S:S,'ball combine if not wild'!Q:Q,"="&'rtp before multiplier'!B6,'ball combine if not wild'!R:R,"="&'rtp before multiplier'!C6)/D6 -> 253 | F6: =E6-F7*2-E8 -> 210 | G6: =F6*D6 -> 3780 | H6: =G6/$E$2 -> 0.00026420356 | I6: 25 | J6: =H6*I6 -> 0.0066050891 | O6: 2 | P6: {=INDEX($H:$H,MATCH(1,($A:$A=P$3)*($C:$C=$O6),0))} -> 0.0073756828 | Q6: {=INDEX($H:$H,MATCH(1,($A:$A=Q$3)*($C:$C=$O6),0))} -> 0.014063598 | R6: {=INDEX($H:$H,MATCH(1,($A:$A=R$3)*($C:$C=$O6),0))} -> 0.024322454 | S6: {=INDEX($H:$H,MATCH(1,($A:$A=S$3)*($C:$C=$O6),0))} -> 0.038919881 | T6: {=INDEX($H:$H,MATCH(1,($A:$A=T$3)*($C:$C=$O6),0))} -> 0.058402227
A7: 9 | B7: 8 | C7: 4 | D7: =COUNTIFS('ball combine if not wild'!Q:Q,"="&'rtp before multiplier'!B7,'ball combine if not wild'!R:R,"="&'rtp before multiplier'!C7) -> 9 | E7: =SUMIFS('ball combine if not wild'!S:S,'ball combine if not wild'!Q:Q,"="&'rtp before multiplier'!B7,'ball combine if not wild'!R:R,"="&'rtp before multiplier'!C7)/D7 -> 22 | F7: =E7-E8 -> 21 | G7: =F7*D7 -> 189 | H7: =G7/$E$2 -> 1.3210178e-05 | I7: 50 | J7: =H7*I7 -> 0.00066050891 | O7: 3 | P7: {=INDEX($H:$H,MATCH(1,($A:$A=P$3)*($C:$C=$O7),0))} -> 0.00026420356 | Q7: {=INDEX($H:$H,MATCH(1,($A:$A=Q$3)*($C:$C=$O7),0))} -> 0.0007968044 | R7: {=INDEX($H:$H,MATCH(1,($A:$A=R$3)*($C:$C=$O7),0))} -> 0.0019720909 | S7: {=INDEX($H:$H,MATCH(1,($A:$A=S$3)*($C:$C=$O7),0))} -> 0.0042348057 | T7: {=INDEX($H:$H,MATCH(1,($A:$A=T$3)*($C:$C=$O7),0))} -> 0.008155922
A8: 9 | B8: 9 | C8: 6 | D8: =COUNTIFS('ball combine if not wild'!Q:Q,"="&'rtp before multiplier'!B8,'ball combine if not wild'!R:R,"="&'rtp before multiplier'!C8) -> 1 | E8: =SUMIFS('ball combine if not wild'!S:S,'ball combine if not wild'!Q:Q,"="&'rtp before multiplier'!B8,'ball combine if not wild'!R:R,"="&'rtp before multiplier'!C8)/D8 -> 1 | F8: =E8 -> 1 | G8: =F8*D8 -> 1 | H8: =G8/$E$2 -> 6.9895122e-08 | I8: 250 | J8: =H8*I8 -> 1.7473781e-05 | O8: 4 | P8: {=INDEX($H:$H,MATCH(1,($A:$A=P$3)*($C:$C=$O8),0))} -> 1.3210178e-05 | Q8: {=INDEX($H:$H,MATCH(1,($A:$A=Q$3)*($C:$C=$O8),0))} -> 6.290561e-05 | R8: {=INDEX($H:$H,MATCH(1,($A:$A=R$3)*($C:$C=$O8),0))} -> 0.00021912121 | S8: {=INDEX($H:$H,MATCH(1,($A:$A=S$3)*($C:$C=$O8),0))} -> 0.00062276554 | T8: {=INDEX($H:$H,MATCH(1,($A:$A=T$3)*($C:$C=$O8),0))} -> 0.0015292354
A9: 10 | B9: 0 | C9: 0 | D9: =COUNTIFS('ball combine if not wild'!Q:Q,"="&'rtp before multiplier'!B9,'ball combine if not wild'!R:R,"="&'rtp before multiplier'!C9) -> 1 | E9: =SUMIFS('ball combine if wild'!S:S,'ball combine if wild'!Q:Q,"="&'rtp before multiplier'!B9,'ball combine if wild'!R:R,"="&'rtp before multiplier'!C9)/D9 -> 30045015 | G9: =E9-SUM(G10:G15) -> 25228941 | H9: =G9/$E$9 -> 0.83970472 | O9: 6 | P9: {=INDEX($H:$H,MATCH(1,($A:$A=P$3)*($C:$C=$O9),0))} -> 6.9895122e-08 | Q9: {=INDEX($H:$H,MATCH(1,($A:$A=Q$3)*($C:$C=$O9),0))} -> 6.9895122e-07 | R9: {=INDEX($H:$H,MATCH(1,($A:$A=R$3)*($C:$C=$O9),0))} -> 3.8442317e-06 | S9: {=INDEX($H:$H,MATCH(1,($A:$A=S$3)*($C:$C=$O9),0))} -> 1.5376927e-05 | T9: {=INDEX($H:$H,MATCH(1,($A:$A=T$3)*($C:$C=$O9),0))} -> 4.9975012e-05
A10: 10 | B10: 3 | C10: 1 | D10: =COUNTIFS('ball combine if not wild'!Q:Q,"="&'rtp before multiplier'!B10,'ball combine if not wild'!R:R,"="&'rtp before multiplier'!C10) -> 6 | E10: =SUMIFS('ball combine if wild'!S:S,'ball combine if wild'!Q:Q,"="&'rtp before multiplier'!B10,'ball combine if wild'!R:R,"="&'rtp before multiplier'!C10)/D10 -> 888030 | F10: =E10-F11*3-F12*2-F13*9-F14*6-E15 -> 721962 | G10: =F10*D10 -> 4331772 | H10: =G10/$E$9 -> 0.14417606 | I10: 2 | J10: =H10*I10 -> 0.28835213
A11: 10 | B11: 5 | C11: 2 | D11: =COUNTIFS('ball combine if not wild'!Q:Q,"="&'rtp before multiplier'!B11,'ball combine if not wild'!R:R,"="&'rtp before multiplier'!C11) -> 9 | E11: =SUMIFS('ball combine if wild'!S:S,'ball combine if wild'!Q:Q,"="&'rtp before multiplier'!B11,'ball combine if wild'!R:R,"="&'rtp before multiplier'!C11)/D11 -> 53130 | F11: =E11-F13*4-F14*4-E15 -> 46949 | G11: =F11*D11 -> 422541 | H11: =G11/$E$9 -> 0.014063598 | I11: 5 | J11: =H11*I11 -> 0.070317988
A12: 10 | B12: 6 | C12: 2 | D12: =COUNTIFS('ball combine if not wild'!Q:Q,"="&'rtp before multiplier'!B12,'ball combine if not wild'!R:R,"="&'rtp before multiplier'!C12) -> 6 | E12: =SUMIFS('ball combine if wild'!S:S,'ball combine if wild'!Q:Q,"="&'rtp before multiplier'!B12,'ball combine if wild'!R:R,"="&'rtp before multiplier'!C12)/D12 -> 10626 | F12: =E12-F13*3-F14*3-E15 -> 5985 | G12: =F12*D12 -> 35910 | H12: =G12/$E$9 -> 0.0011952066 | I12: 5 | J12: =H12*I12 -> 0.005976033
A13: 10 | B13: 7 | C13: 3 | D13: =COUNTIFS('ball combine if not wild'!Q:Q,"="&'rtp before multiplier'!B13,'ball combine if not wild'!R:R,"="&'rtp before multiplier'!C13) -> 18 | E13: =SUMIFS('ball combine if wild'!S:S,'ball combine if wild'!Q:Q,"="&'rtp before multiplier'!B13,'ball combine if wild'!R:R,"="&'rtp before multiplier'!C13)/D13 -> 1771 | F13: =E13-F14*2-E15 -> 1330 | G13: =F13*D13 -> 23940 | H13: =G13/$E$9 -> 0.0007968044 | I13: 25 | J13: =H13*I13 -> 0.01992011
A14: 10 | B14: 8 | C14: 4 | D14: =COUNTIFS('ball combine if not wild'!Q:Q,"="&'rtp before multiplier'!B14,'ball combine if not wild'!R:R,"="&'rtp before multiplier'!C14) -> 9 | E14: =SUMIFS('ball combine if wild'!S:S,'ball combine if wild'!Q:Q,"="&'rtp before multiplier'!B14,'ball combine if wild'!R:R,"="&'rtp before multiplier'!C14)/D14 -> 231 | F14: =E14-E15 -> 210 | G14: =F14*D14 -> 1890 | H14: =G14/$E$9 -> 6.290561e-05 | I14: 50 | J14: =H14*I14 -> 0.0031452805 | O14: 1 | P14: =SUMPRODUCT($P$4:$T$4,P5:T5) -> 0.1308303
A15: 10 | B15: 9 | C15: 6 | D15: =COUNTIFS('ball combine if not wild'!Q:Q,"="&'rtp before multiplier'!B15,'ball combine if not wild'!R:R,"="&'rtp before multiplier'!C15) -> 1 | E15: =SUMIFS('ball combine if wild'!S:S,'ball combine if wild'!Q:Q,"="&'rtp before multiplier'!B15,'ball combine if wild'!R:R,"="&'rtp before multiplier'!C15)/D15 -> 21 | F15: =E15 -> 21 | G15: =F15*D15 -> 21 | H15: =G15/$E$9 -> 6.9895122e-07 | I15: 250 | J15: =H15*I15 -> 0.00017473781 | O15: 2 | P15: =SUMPRODUCT($P$4:$T$4,P6:T6) -> 0.013239205
A16: 11 | B16: 0 | C16: 0 | D16: =COUNTIFS('ball combine if not wild'!Q:Q,"="&'rtp before multiplier'!B16,'ball combine if not wild'!R:R,"="&'rtp before multiplier'!C16) -> 1 | E16: =SUMIFS('ball combine if wild'!T:T,'ball combine if wild'!Q:Q,"="&'rtp before multiplier'!B16,'ball combine if wild'!R:R,"="&'rtp before multiplier'!C16)/D16 -> 54627300 | G16: =E16-SUM(G17:G22) -> 43010034 | H16: =G16/$E$16 -> 0.78733589 | O16: 3 | P16: =SUMPRODUCT($P$4:$T$4,P7:T7) -> 0.00096859218
A17: 11 | B17: 3 | C17: 1 | D17: =COUNTIFS('ball combine if not wild'!Q:Q,"="&'rtp before multiplier'!B17,'ball combine if not wild'!R:R,"="&'rtp before multiplier'!C17) -> 6 | E17: =SUMIFS('ball combine if wild'!T:T,'ball combine if wild'!Q:Q,"="&'rtp before multiplier'!B17,'ball combine if wild'!R:R,"="&'rtp before multiplier'!C17)/D17 -> 2220075 | F17: =E17-F18*3-F19*2-F20*9-F21*6-E22 -> 1674432 | G17: =F17*D17 -> 10046592 | H17: =G17/$E$16 -> 0.18391156 | I17: 2 | J17: =H17*I17 -> 0.36782312 | O17: 4 | P17: =SUMPRODUCT($P$4:$T$4,P8:T8) -> 0.00012085791
A18: 11 | B18: 5 | C18: 2 | D18: =COUNTIFS('ball combine if not wild'!Q:Q,"="&'rtp before multiplier'!B18,'ball combine if not wild'!R:R,"="&'rtp before multiplier'!C18) -> 9 | E18: =SUMIFS('ball combine if wild'!T:T,'ball combine if wild'!Q:Q,"="&'rtp before multiplier'!B18,'ball combine if wild'!R:R,"="&'rtp before multiplier'!C18)/D18 -> 177100 | F18: =E18-F20*4-F21*4-E22 -> 147630 | G18: =F18*D18 -> 1328670 | H18: =G18/$E$16 -> 0.024322454 | I18: 5 | J18: =H18*I18 -> 0.12161227 | O18: 6 | P18: =SUMPRODUCT($P$4:$T$4,P9:T9) -> 2.9006476e-06
A19: 11 | B19: 6 | C19: 2 | D19: =COUNTIFS('ball combine if not wild'!Q:Q,"="&'rtp before multiplier'!B19,'ball combine if not wild'!R:R,"="&'rtp before multiplier'!C19) -> 6 | E19: =SUMIFS('ball combine if wild'!T:T,'ball combine if wild'!Q:Q,"="&'rtp before multiplier'!B19,'ball combine if wild'!R:R,"="&'rtp before multiplier'!C19)/D19 -> 42504 | F19: =E19-F20*3-F21*3-E22 -> 20349 | G19: =F19*D19 -> 122094 | H19: =G19/$E$16 -> 0.0022350363 | I19: 5 | J19: =H19*I19 -> 0.011175182
A20: 11 | B20: 7 | C20: 3 | D20: =COUNTIFS('ball combine if not wild'!Q:Q,"="&'rtp before multiplier'!B20,'ball combine if not wild'!R:R,"="&'rtp before multiplier'!C20) -> 18 | E20: =SUMIFS('ball combine if wild'!T:T,'ball combine if wild'!Q:Q,"="&'rtp before multiplier'!B20,'ball combine if wild'!R:R,"="&'rtp before multiplier'!C20)/D20 -> 8855 | F20: =E20-F21*2-E22 -> 5985 | G20: =F20*D20 -> 107730 | H20: =G20/$E$16 -> 0.0019720909 | I20: 25 | J20: =H20*I20 -> 0.049302272
A21: 11 | B21: 8 | C21: 4 | D21: =COUNTIFS('ball combine if not wild'!Q:Q,"="&'rtp before multiplier'!B21,'ball combine if not wild'!R:R,"="&'rtp before multiplier'!C21) -> 9 | E21: =SUMIFS('ball combine if wild'!T:T,'ball combine if wild'!Q:Q,"="&'rtp before multiplier'!B21,'ball combine if wild'!R:R,"="&'rtp before multiplier'!C21)/D21 -> 1540 | F21: =E21-E22 -> 1330 | G21: =F21*D21 -> 11970 | H21: =G21/$E$16 -> 0.00021912121 | I21: 50 | J21: =H21*I21 -> 0.01095606
